Workbook

Sheet Как читать
B1: Книга «Модель расчёт v2» — стационарная часть математической модели местной вытяжной вентиляции сварочного участка
B2: Версия 12.10.2026. Каждая цифра здесь считается формулой Excel — можно поменять синюю ячейку и увидеть, как меняется всё остальное.
B4: ЦВЕТА
B5: Синий шрифт на жёлтом — исходные данные (их можно менять). У каждого — источник в последней колонке.
B6: Чёрный шрифт — формула. Зелёный — формула-ссылка на ячейку другого листа.
B7: Оранжевая заливка — число, которое посчитало расчётное ядро (программа на TypeScript, папка vent-sim). Нужно только для сверки на листе «8 Сверка».
B9: СТАТУСЫ ИСТОЧНИКОВ
B10: [Н] — норматив РФ (ГОСТ, СП, СанПиН, методика из перечня Минприроды). [С] — российский справочник или учебник.
B11: [Д] — допущение демонстрационного примера (заменяется паспортом оборудования реального объекта). [А] — параметр, выбранный автором (проверена чувствительность).
B12: [П] — источник найден, но страницу/таблицу надо сверить по бумажной книге. [М] — инженерная модель (приём расчёта, не норматив).
B14: ПОРЯДОК ЛИСТОВ = ПОРЯДОК РАСЧЁТА
B15: 1 Исходные — все входные величины в одном месте.
... B37: 3. Энергия вентилятора общеобменной: при регулировании по выделениям расход бывает больше расчётного; вентилятор теперь подбирается на максимальный расход (иначе мощность считалась при нереальном давлении).

Sheet Источники
A1: Источники: нормативы и справочники, на которых стоит каждая формула и каждое число
A2: Актуальность нормативов проверена 11.10.2026. Ссылка ведёт на текст документа или на его карточку в официальном каталоге. [Н] — норматив РФ, [С] — справочник/учебник.
A4: № | B4: Документ | C4: Что из него взято | D4: Где в книге | E4: Статус на 10.2026 | F4: Ссылка
A5: 1 | B5: СП 60.13330.2020 «Отопление, вентиляция и кондиционирование воздуха» (с изм. № 1–6) [Н] | C5: Прил. Г, ф. (Г.2) — воздухообмен по вредным веществам с учётом местных отсосов; п. 7.4.1 — запрет расчёта по кратности для рабочей зоны; п. 7.4.3 — суммирование однонаправленных веществ; п. 5.11 — приток ≤ 30 % ПДК | D5: лист 3 | E5: действует; использованные пункты изменениями 1–6 не затронуты | F5: https://base.garant.ru/400536193/
A6: 2 | B6: СанПиН 1.2.3685-21 «Гигиенические нормативы и требования к обеспечению безопасности и (или) безвредности для человека факторов среды обитания» [Н] | C6: Табл. 2.1 — ПДК в воздухе рабочей зоны: Mn в сварочном аэрозоле 0,6/0,2; Fe₂O₃ 6; SiO₂ 3/1; табл. 1.1 — ПДК атмосферного воздуха (фон притока) | D6: листы 1, 3 | E6: действует (ред. от 24.12.2025), срок — до 01.03.2027 | F6: https://www.consultant.ru/document/cons_doc_LAW_375839/
A7: 3 | B7: ГОСТ 12.3.003-86 «ССБТ. Работы электросварочные. Требования безопасности» [Н] | C7: П. 2.11.1 — местный отсос сварочного стола не менее 1500 м³/ч | D7: листы 1, 10 | E7: действует | F7: https://meganorm.ru/Index1/7/7136.htm
A8: 4 | B8: ГОСТ 12.1.005-88 «ССБТ. Общие санитарно-гигиенические требования к воздуху рабочей зоны» [Н] | C8: Табл. 1 — микроклимат: категория IIб, холодный период — 17–19 °C; п. 3.4 — Σ C/ПДК ≤ 1 | D8: лист 1 | E8: действует | F8: https://legalacts.ru/doc/gost-121005-88-mezhgosudarstvennyi-standart-sistema-standartov-bezopasnosti/
A9: 5 | B9: ГОСТ Р 56164-2014 «Выбросы загрязняющих веществ в атмосферу. Метод расчёта выбросов при сварочных работах на основе удельных показателей» [Н] | C9: Табл. 1 — удельные выделения на 1 кг проволоки Св-08Г2С (10,0 / 7,67 / 1,90 / 0,43 г/кг) | D9: листы 1, 2 | E9: действует с 01.07.2015 | F9: https://cn.gostinfo.ru/catalog/Details/?id=5484995
A10: 6 | B10: Методика расчёта выделений (выбросов) загрязняющих веществ в атмосферу при сварочных работах (на основе удельных показателей). — СПб.: НИИ Атмосфера, 1997 (изд. 2021) [Н] | C10: Табл. 1 — те же удельные выделения; разд. 2.1, прим. 1 — η = 0,8 при отсутствии данных | D10: листы 1, 2 | E10: в перечне методик Минприроды (распоряжение № 35-р от 14.12.2020) | F10: PDF издания 2021 г. — у автора
A11: 7 | B11: СП 131.13330.2025 «Строительная климатология» [Н] | C11: Табл. 5.1 — Москва: средняя температура отопительного периода −1,7 °C, продолжительность 202 сут | D11: листы 1, 7 | E11: действует | F11: текст сверен 11.10.2026 (PDF — у автора)
A12: 8 | B12: ГОСТ 10921-2017 «Вентиляторы радиальные и осевые. Методы аэродинамических испытаний» [Н] | C12: Разд. 14 — пересчёт характеристики на другую частоту (Q ~ n, p ~ n²); стандартные условия ρ = 1,2 кг/м³ | D12: листы 1, 6 | E12: действует | F12: https://meganorm.ru/Index/69/69841.htm
A13: 9 | B13: ГОСТ IEC 60034-30-1-2016 «Машины электрические вращающиеся. Классы КПД» [Н] | C13: Табл. 1 — КПД двигателя IE3 2,2 кВт, 4 полюса: 86,7 % | D13: лист 6 | E13: действует | F13: https://cn.gostinfo.ru/catalog/Details/?id=6316233
A14: 10 | B14: ГОСТ 7192-89 «Механизмы исполнительные электрические постоянной скорости ГСП» [Н] | C14: Ряд времени полного хода (… 8; 10; 15; 25; 30; 63 … с) | D14: лист 10 | E14: действует | F14: https://dnaop.com/html/69390/doc-%D0%93%D0%9E%D0%A1%D0%A2_7192-89
A15: 11 | B15: Идельчик И.Е. Справочник по гидравлическим сопротивлениям / под ред. М.О. Штейнберга. — 3-е изд. — М.: Машиностроение, 1992. — 672 с. [С] | C15: Диагр. 3-6 (с. 127) — вход в зонт; 5-2 (с. 211) и ф. (5-6), (5-7) — диффузор; 6-1 (с. 277–278) — отводы; 7-4 (с. 346) и табл. 7-1 (с. 335) — тройники; 9-17 (с. 452–453) — заслонка | D15: листы 4, 5 | E15: справочник; страницы сверены по книге | F15: книга (PDF — у автора)
A16: 12 | B16: Альтшуль А.Д. Гидравлические сопротивления. — М.: Недра, 1982 [С] | C16: Формула трения λ = 0,11·(kэ/d + 68/Re)^0,25 | D16: лист 5 | E16: справочник | F16: книга
... A21: 17 | B21: Копылов И.П. Электрические машины: учебник [С] | C21: Разделение потерь двигателя на постоянные и переменные — КПД при неполной загрузке | D21: лист 6 | E21: учебник [П: страница] | F21: книга
B23: Зарубежные источники в расчёте не используются, кроме типовой таблицы КПД частотника (US DOE) — до паспорта ПЧ (лист 6).

Sheet 1 Исходные
A1: Исходные данные
A2: Все величины, от которых зависит расчёт. Меняйте только синие ячейки. Источник каждой — в колонке H.
A4: № | B4: Величина | C4: Обозн. | D4: Значение | E4: Ед. | F4: Формула (как в книге) | G4: Простыми словами — что это и зачем | H4: Источник / статус
A5: Воздух
A6: 1 | B6: Плотность воздуха | C6: ρ | D6: 1.2 | E6: кг/м³ | F6: — | G6: Сколько весит кубометр воздуха. 1,2 — стандартные условия, при которых испытывают вентиляторы. | H6: ГОСТ 10921-2017, разд. 14 [Н]
A7: 2 | B7: Кинематическая вязкость воздуха (20 °C) | C7: ν | D7: 1.506e-05 | E7: м²/с | F7: — | G7: Насколько воздух «вязкий». Нужна для числа Рейнольдса (режим течения). | H7: Варгафтик Н.Б., 1972 [С][П]
A8: 3 | B8: Теплоёмкость воздуха | C8: c | D8: 1.005 | E8: кДж/(кг·°C) | F8: — | G8: Сколько тепла надо, чтобы нагреть 1 кг воздуха на 1 °C. | H8: Варгафтик Н.Б., 1972 [С][П]
A9: Воздуховоды
A10: 4 | B10: Эквивалентная шероховатость стали | C10: kэ | D10: 0.0001 | E10: м | F10: — | G10: Насколько шершавая стенка воздуховода — влияет на трение. | H10: Справочник проектировщика, ч. 3, кн. 2, 1992; Альтшуль, 1982 [С][П]
A11: 5 | B11: Минимальная транспортная скорость | C11: w_мин | D11: 8 | E11: м/с | F11: — | G11: Ниже этой скорости сварочная пыль начинает оседать в воздуховоде. | H11: Боломатов В.Н., АВОК, 2021, № 3, табл. 4 (8–14 м/с) [С]
A12: Сварка
A13: 6 | B13: Число постов | C13: n | D13: 3 | E13: шт | F13: — | G13: Сколько сварщиков работает одновременно (расчётный случай — все сразу). | H13: Демо-пример (диплом) [Д]
A14: 7 | B14: Сварочный ток | C14: I | D14: 225 | E14: А | F14: — | G14: Ток полуавтомата. Чем больше ток, тем больше плавится проволоки и больше дыма. | H14: Режим для Ø1,2 мм [Д]
A15: 8 | B15: Диаметр проволоки | C15: d | D15: 1.2 | E15: мм | F15: — | H15: Св-08Г2С Ø1,2 [Д]
A16: 9 | B16: Вылет электрода | C16: l | D16: 15 | E16: мм | F16: — | G16: Длина проволоки от токоподвода до дуги (10–20 мм). | H16: Соколов и др., ВолгГТУ, 2016 [С]
A17: 10 | B17: Расход местного отсоса на пост | C17: Q_тр | D17: 1500 | E17: м³/ч | F17: — | G17: Минимум по ГОСТ для сварочного стола. | H17: ГОСТ 12.3.003-86, п. 2.11.1 [Н]
A18: 11 | B18: Эффективность местного отсоса | C18: η | D18: 0.8 | E18: — | F18: — | G18: Какую долю дыма ловит отсос. Остальное (20 %) уходит в цех. | H18: Методика 1997 (приказ Госкомэкологии № 158), разд. 2.1, прим. 1 [Н]
A19: Удельные выделения, г на 1 кг проволоки Св-08Г2С (сварка в CO₂)
A20: 12 | B20: Сварочный аэрозоль (всего) | C20: g_аэр | D20: 10 | E20: г/кг | F20: — | G20: Сколько всего дыма (твёрдых частиц) на килограмм проволоки. | H20: Методика 1997, табл. 1 [Н]
A21: 13 | B21: в т.ч. железа оксид | C21: g_Fe | D21: 7.67 | E21: г/кг | F21: — | H21: там же [Н]
A22: 14 | B22: в т.ч. марганец и его соединения | C22: g_Mn | D22: 1.9 | E22: г/кг | F22: — | G22: Самое вредное в сварочном дыме — по нему считается вентиляция. | H22: Методика 1997 (изд. 2021), табл. 1, столбец 5 «марганец и его соединения» — по Mn, без пересчёта на MnO₂ [Н] (сверено)
A23: 15 | B23: в т.ч. пыль с SiO₂ | C23: g_SiO₂ | D23: 0.43 | E23: г/кг | F23: — | H23: там же [Н]
A24: ПДК (рабочая зона) и фон в приточном воздухе
A25: 16 | B25: ПДК марганца (сварочный аэрозоль, Mn ≤ 20 %), среднесменная | C25: ПДК_Mn | D25: 0.2 | E25: мг/м³ | F25: — | G25: Предельная концентрация в воздухе рабочей зоны. Берём среднесменную (строже максимально разовой 0,6) — в запас. | H25: СанПиН 1.2.3685-21, табл. 2.1 [Н] (сверено)
A26: 17 | B26: Марганец в приточном (наружном) воздухе | C26: q_пр,Mn | D26: 0.001 | E26: мг/м³ | F26: — | G26: Сколько марганца уже есть в наружном воздухе. Берём ПДК атмосферы — верхняя оценка. | H26: СанПиН 1.2.3685-21, табл. 1.1, поз. 302 [Н]; СП 60, п. 5.11
A27: 18 | B27: ПДК железа оксида | C27: ПДК_Fe | D27: 6 | E27: мг/м³ | F27: — | H27: СанПиН 1.2.3685-21, табл. 2.1, стр. 1031 «диЖелезо триоксид», Ф, 4 кл. [Н] (сверено)
A28: 19 | B28: Железа оксид в приточном воздухе | C28: q_пр,Fe | D28: 0.04 | E28: мг/м³ | F28: — | H28: СанПиН, табл. 1.1 (ПДК с.с. атм.) [П]
A29: 20 | B29: ПДК кремния диоксида аморфного (аэрозоль конденсации), с.с. | C29: ПДК_SiO₂ | D29: 1 | E29: мг/м³ | F29: — | H29: СанПиН 1.2.3685-21, табл. 2.1, стр. 1150 (3/1 мг/м³) [Н] (сверено)
A30: Климат (холодный период) и помещение
A31: 21 | B31: Температура в цехе | C31: t_в | D31: 18 | E31: °C | F31: — | G31: Середина оптимума 17–19 °C для работ категории IIб. | H31: ГОСТ 12.1.005-88, табл. 1: категория IIб, холодный период — оптимум 17–19 °C [Н] (сверено)
A32: 22 | B32: Средняя температура отопительного периода (Москва) | C32: t_оп | D32: -1.7 | E32: °C | F32: — | G32: Средняя температура наружного воздуха за отопительный период. | H32: СП 131.13330.2025, табл. 5.1 [Н]
A33: 23 | B33: Продолжительность отопительного периода | C33: z_оп | D33: 202 | E33: сут | F33: — | H33: СП 131.13330.2025, табл. 5.1 [Н]
A34: 24 | B34: Длительность смены | C34: t_см | D34: 8 | E34: ч | F34: — | H34: [Д]
A35: 25 | B35: Объём цеха | C35: V | D35: 16588.8 | E35: м³ | F35: 48 × 24 × 14,4 м | G35: Нужен для динамики (как быстро растёт концентрация), на стационарный расчёт не влияет. | H35: Диплом [Д]

Sheet 2 Выделения
A1: Выделение вредных веществ при сварке
A2: Шаг 1: по току считаем, сколько проволоки плавится в час. Шаг 2: умножаем на удельные выделения из Методики. Шаг 3: делим — η ловит отсос, (1 − η) уходит в цех.
A4: № | B4: Величина | C4: Обозн. | D4: Значение | E4: Ед. | F4: Формула (как в книге) | G4: Простыми словами — что это и зачем | H4: Источник / статус
A5: Расход проволоки
A6: 1 | B6: Коэффициент расплавления | C6: α_р | D6: =9.05+0.00031*'1 Исходные'!$D$14*'1 Исходные'!$D$16/'1 Исходные'!$D$15^2 -> 9.7765625 | E6: г/(А·ч) | F6: α_р = 9,05 + 3,1·10⁻⁴·I·l/d² | G6: Сколько граммов проволоки плавит каждый ампер за час. Растёт с током и вылетом (проволока подогревается током). | H6: Соколов Г.Н. и др. Технология и материалы для сварки и наплавки. ВолгГТУ, 2016, ф. (3.22) [С][П]
A7: 2 | B7: Расход проволоки | C7: B | D7: ='2 Выделения'!$D$6*'1 Исходные'!$D$14/1000 -> 2.1997266 | E7: кг/ч | F7: B = α_р·I / 1000 | G7: Килограммы проволоки в час на одном посту. | H7: там же
A8: Выделение на одном посту (дуга горит)
A9: 3 | B9: Аэрозоль | C9: G_аэр | D9: ='1 Исходные'!$D$20*'2 Выделения'!$D$7 -> 21.997266 | E9: г/ч | F9: G = g·B | G9: Граммов дыма в час. | H9: Методика 1997, разд. 2.1, ф. (2.1) [Н]
A10: 4 | B10: Марганец | C10: G_Mn | D10: ='1 Исходные'!$D$22*'2 Выделения'!$D$7 -> 4.1794805 | E10: г/ч | F10: G = g·B | H10: там же
A11: 5 | B11: Железа оксид | C11: G_Fe | D11: ='1 Исходные'!$D$21*'2 Выделения'!$D$7 -> 16.871903 | E11: г/ч | F11: G = g·B | H11: там же
A12: 6 | B12: Пыль с SiO₂ | C12: G_SiO₂ | D12: ='1 Исходные'!$D$23*'2 Выделения'!$D$7 -> 0.94588242 | E12: г/ч | F12: G = g·B | H12: там же
A13: 7 | B13: Проверка: сумма компонентов = аэрозоль | D13: ='1 Исходные'!$D$21+'1 Исходные'!$D$22+'1 Исходные'!$D$23-'1 Исходные'!$D$20 -> 0 | E13: г/кг | F13: Σg_i − g_аэр | G13: Должно быть 0: в Методике аэрозоль = сумма твёрдых компонентов. Это проверка, что числа переписаны без ошибки. | H13: проверка
A14: Куда уходит марганец (все посты)
A15: 8 | B15: Выделяется на всех постах | C15: ΣG_Mn | D15: ='2 Выделения'!$D$10*'1 Исходные'!$D$13*1000 -> 12538.441 | E15: мг/ч | F15: n·G_Mn
A16: 9 | B16: Ловят местные отсосы | C16: η·ΣG | D16: ='1 Исходные'!$D$18*'2 Выделения'!$D$15 -> 10030.753 | E16: мг/ч | F16: η·ΣG | G16: Уходит через отсос → фильтр → выброс. | H16: Методика 1997, разд. 2.1 [Н]
A17: 10 | B17: Поступает в воздух цеха | C17: m_по | D17: =(1-'1 Исходные'!$D$18)*'2 Выделения'!$D$15 -> 2507.6883 | E17: мг/ч | F17: (1 − η)·ΣG | G17: Вот это и должна разбавить вентиляция — это m_по в формуле СП 60. | H17: СП 60.13330.2020 (обозначение m_po) [Н]
A18: 11 | B18: Железа оксид в воздух цеха | C18: m_Fe | D18: =(1-'1 Исходные'!$D$18)*'2 Выделения'!$D$11*'1 Исходные'!$D$13*1000 -> 10123.142 | E18: мг/ч | F18: (1 − η)·n·G_Fe
A19: 12 | B19: SiO₂ в воздух цеха | C19: m_SiO₂ | D19: =(1-'1 Исходные'!$D$18)*'2 Выделения'!$D$12*'1 Исходные'!$D$13*1000 -> 567.52945 | E19: мг/ч | F19: (1 − η)·n·G_SiO₂
B20: Оседание аэрозоля (коэффициент 0,4 по Методике, разд. 2.3) в базовом расчёте НЕ учитывается — это запас. Вариант с оседанием посчитан в ядре (лист 9).

Sheet 3 СП 60
A1: Воздухообмен по СП 60.13330.2020 (ассимиляция вредных веществ)
A2: Формула СП 60 (та же — СНиП 2.04.05-91*, прил. 17): L = L_wz + (m_по − L_wz·(q_wz − q_пр)) / (q_l − q_пр). L — сколько всего воздуха надо удалить из цеха (= подать притоком). Сюда входят и местные отсосы L_wz, поэтому общеобменная = L − L_wz.
A4: № | B4: Величина | C4: Обозн. | D4: Значение | E4: Ед. | F4: Формула (как в книге) | G4: Простыми словами — что это и зачем | H4: Источник / статус
A5: Марганец (лимитирующее вещество)
A6: 1 | B6: Воздух, удаляемый местными отсосами | C6: L_wz | D6: ='1 Исходные'!$D$17*'1 Исходные'!$D$13 -> 4500 | E6: м³/ч | F6: L_wz = n·Q_тр | G6: Отсосы уносят воздух из цеха вместе с остатком дыма — этот воздух тоже участвует в разбавлении. | H6: СП 60.13330.2020 [Н]
A7: 2 | B7: Допустимая концентрация в рабочей зоне | C7: q_wz | D7: ='1 Исходные'!$D$25 -> 0.2 | E7: мг/м³ | F7: q_wz = ПДК | H7: СП 60, ГОСТ 12.1.005-88 [Н]
A8: 3 | B8: Концентрация в приточном воздухе | C8: q_пр | D8: ='1 Исходные'!$D$26 -> 0.001 | E8: мг/м³
A9: 4 | B9: Концентрация в воздухе, удаляемом из верхней зоны | C9: q_l | D9: ='3 СП 60'!$D$7 -> 0.2 | E9: мг/м³ | F9: q_l = q_wz (допущение) | G9: Принято, что воздух перемешан полностью. На деле сварочный дым поднимается и наверху концентрация больше — значит реальный расход меньше, допущение идёт в запас. | H9: [Д] — в запас
A10: 5 | B10: Весь воздухообмен (приток = вся вытяжка) | C10: L | D10: ='3 СП 60'!$D$6+('2 Выделения'!$D$17-'3 СП 60'!$D$6*('3 СП 60'!$D$7-'3 СП 60'!$D$8))/('3 СП 60'!$D$9-'3 СП 60'!$D$8) -> 12601.449 | E10: м³/ч | F10: L = L_wz + (m_по − L_wz·(q_wz − q_пр))/(q_l − q_пр) | G10: Сколько воздуха надо удалить всего, чтобы марганца было не больше ПДК. | H10: СП 60.13330.2020 [Н]
A11: 6 | B11: Общеобменная вытяжка (сверх местных отсосов) | C11: L_оо | D11: =MAX(0,'3 СП 60'!$D$10-'3 СП 60'!$D$6) -> 8101.4486 | E11: м³/ч | F11: L_оо = L − L_wz | G11: Столько должен удалять вентилятор общеобменной вентиляции.
A12: 7 | B12: Проверка: при q_l = q_wz формула упрощается | C12: L | D12: ='2 Выделения'!$D$17/('3 СП 60'!$D$7-'3 СП 60'!$D$8) -> 12601.449 | E12: м³/ч | F12: L = m_по/(q_wz − q_пр) | G12: Должно совпасть с L выше — значит формула введена верно. | H12: алгебра
A13: 8 | B13: Проверка: концентрация при найденном L | C13: C | D13: ='3 СП 60'!$D$8+'2 Выделения'!$D$17/'3 СП 60'!$D$10 -> 0.2 | E13: мг/м³ | F13: C = q_пр + m_по/L | G13: Должно получиться ровно ПДК (0,2). | H13: баланс массы
A14: 9 | B14: Как было в модели до 11.10.2026 (ОШИБКА для центральной вытяжки) | C14: L_оо,стар | D14: ='2 Выделения'!$D$17/('3 СП 60'!$D$7-'3 СП 60'!$D$8) -> 12601.449 | E14: м³/ч | F14: L_оо = m_по/(ПДК − q_пр) | G14: Весь потребный воздух отдавали общеобменной и ещё добавляли местные отсосы сверху — воздух отсосов считался дважды. Для схемы с возвратом воздуха (диплом) эта формула верна — см. ниже. | H14: ошибка — в запас
A15: 10 | B15: Перерасход из-за ошибки | C15: ΔL | D15: ='3 СП 60'!$D$14-'3 СП 60'!$D$11 -> 4500 | E15: м³/ч | F15: L_оо,стар − L_оо | G15: Ровно расход местных отсосов.
A16: Другие вещества — проверка, что лимитирует марганец
A17: 11 | B17: Весь воздухообмен по железа оксиду | C17: L_Fe | D17: ='2 Выделения'!$D$18/('1 Исходные'!$D$27-'1 Исходные'!$D$28) -> 1698.5137 | E17: м³/ч | F17: L = m/(ПДК − q_пр) | G17: Меньше, чем по марганцу — значит определяет марганец. | H17: СП 60 [Н]
A18: 12 | B18: Весь воздухообмен по SiO₂ | C18: L_SiO₂ | D18: ='2 Выделения'!$D$19/'1 Исходные'!$D$29 -> 567.52945 | E18: м³/ч | F18: L = m/ПДК | H18: СП 60 [Н]
A19: 13 | B19: Расчётный (наибольший) | C19: L_расч | D19: =MAX('3 СП 60'!$D$10,'3 СП 60'!$D$17,'3 СП 60'!$D$18) -> 12601.449 | E19: м³/ч | F19: max по веществам | G19: Если вещества однонаправленного действия — по СП 60 расходы СКЛАДЫВАЮТСЯ (Σ m_i/(ПДК_i − q_пр,i)). Mn, Fe₂O₃ и SiO₂ к одной группе не относятся. | H19: СП 60.13330.2020 [Н]
A20: Схема диплома: переносной электрофильтр с возвратом очищенного воздуха в цех (L_wz = 0)
A21: 14 | B21: Степень очистки аэрозоля фильтром агрегата | C21: η_ф | D21: 1 | E21: — | G21: 1 — идеальный фильтр. Реальное значение — из паспорта агрегата. Газы (HF, CO, NO₂) электрофильтр не задерживает: для них η_ф = 0. | H21: паспорт [Д]
A22: 15 | B22: Mn в воздух цеха: мимо отсоса + проскок фильтра | C22: m_по | D22: =(1-'1 Исходные'!$D$18+'1 Исходные'!$D$18*(1-'3 СП 60'!$D$21))*'2 Выделения'!$D$15 -> 2507.6883 | E22: мг/ч | F22: m = [(1 − η) + η(1 − η_ф)]·ΣG | G22: Фильтр возвращает воздух в цех вместе с тем, что не поймал. | H22: баланс массы
A23: 16 | B23: Весь воздухообмен = общеобменная (отсосы воздух не удаляют) | C23: L = L_оо | D23: ='3 СП 60'!$D$22/('3 СП 60'!$D$7-'3 СП 60'!$D$8) -> 12601.449 | E23: м³/ч | F23: L = m/(q_wz − q_пр), L_wz = 0 | G23: При η_ф = 1 — ровно столько же воздуха, сколько при центральной вытяжке (L выше). Значит, и тепло то же. Разница — только кто удаляет воздух. | H23: СП 60 [Н]
A24: 17 | B24: Во сколько раз больше, чем при выбросе наружу | D24: ='3 СП 60'!$D$23/'3 СП 60'!$D$10 -> 1 | E24: — | G24: При η_ф = 0,95 → 1,2 раза.
B25: Норматив: СНиП 41-01-2003, п. 7.4.4 — рециркуляция не допускается из систем местных отсосов вредных веществ; исключение — местные отсосы пылевоздушных смесей после очистки от пыли. Для сварочного аэрозоля с Mn (2-й класс) и газами — сверить по действующему СП 60.13330.2020, разд. 7.4 [П].
A26: Что ещё требует СП 60 и как это учтено
B27: 1) Расходы определяются отдельно для тёплого и холодного периодов — в модели считается холодный (по нему максимальные затраты тепла). 2) Теплопоступления от дуги на расход по вредным веществам не влияют (одинаковы во всех режимах) — не моделируются. 3) Рециркуляция не применяется: Mn — 2-й класс опасности. 4) Минимум наружного воздуха на человека (СП 60, прил. [П: номер]) — десятки м³/ч; у нас ≥ 1500 м³/ч на сварщика — выполняется с большим запасом. 5) Местные отсосы и общеобменная вытяжка компенсируются притоком того же расхода — поэтому тепло считается от L (лист 7).

Sheet 4 Таблицы
A1: Характеристика дроссель-клапана (круглый воздуховод): угол → ζ
A2: 0° — открыта, 90° — закрыта. Между точками таблицы ζ интерполируется по логарифму (ζ растёт почти экспоненциально): ln ζ = ln ζ₀ + (α − α₀)/(α₁ − α₀)·(ln ζ₁ − ln ζ₀). Источник: Идельчик И.Е. Справочник по гидравлическим сопротивлениям. 3-е изд. — М.: Машиностроение, 1992, диагр. 9-17, с. 453, кривая 2 (D̄ = 1,0) — сверено; 0° — [Д] (в таблице для кривой 2 нет); 90° — [Д] утечка закрытой заслонки.
A4: α, ° | B4: ζ | C4: ln ζ | D4: Комментарий
A5: 0 | B5: 0.2 | C5: =LN(B5) -> -1.6094379 | D5: [Д] нет в табл.
A6: 10 | B6: 0.52 | C6: =LN(B6) -> -0.65392647 | D6: Идельчик, диагр. 9-17
A7: 20 | B7: 1.54 | C7: =LN(B7) -> 0.43178242 | D7: Идельчик, диагр. 9-17
A8: 30 | B8: 4.5 | C8: =LN(B8) -> 1.5040774 | D8: Идельчик, диагр. 9-17
A9: 40 | B9: 11 | C9: =LN(B9) -> 2.3978953 | D9: Идельчик, диагр. 9-17
A10: 50 | B10: 29 | C10: =LN(B10) -> 3.3672958 | D10: Идельчик, диагр. 9-17
A11: 60 | B11: 105 | C11: =LN(B11) -> 4.6539604 | D11: Идельчик, диагр. 9-17
A12: 70 | B12: 625 | C12: =LN(B12) -> 6.4377516 | D12: Идельчик, диагр. 9-17
A13: 90 | B13: 10000 | C13: =LN(B13) -> 9.2103404 | D13: [Д] закрыто (утечка)
A16: Коэффициент A₁ отвода от угла поворота δ — Идельчик, 1992, диагр. 6-1, с. 278 (таблица), сверено
A17: δ, ° | B17: A₁
A18: 0 | B18: 0
A19: 20 | B19: 0.31
A20: 30 | B20: 0.45
A21: 45 | B21: 0.6
A22: 60 | B22: 0.78
A23: 75 | B23: 0.9
A24: 90 | B24: 1
A25: 110 | B25: 1.13
A26: 130 | B26: 1.2
A27: 150 | B27: 1.28
A28: 180 | B28: 1.4
A31: Диффузор круглый в сети, ζ_д при n = F₁/F₀ = 2, l₀/D₀ = 0 — Идельчик, 1992, диагр. 5-2, с. 211, сверено. Строки — Re·10⁻⁵, столбцы — α, °
A32: Re | B32: ln Re | C32: 3 | D32: 4 | E32: 6 | F32: 8 | G32: 10 | H32: 12 | I32: 14 | J32: 16 | K32: 20 | L32: 30 | M32: 45 | N32: 60 | O32: 90 | P32: 120 | Q32: 180
A33: 50000 | B33: =LN(A33) -> 10.819778 | C33: 0.148 | D33: 0.135 | E33: 0.121 | F33: 0.112 | G33: 0.107 | H33: 0.109 | I33: 0.12 | J33: 0.141 | K33: 0.191 | L33: 0.315 | M33: 0.331 | N33: 0.326 | O33: 0.315 | P33: 0.308 | Q33: 0.298
A34: 100000 | B34: =LN(A34) -> 11.512925 | C34: 0.12 | D34: 0.106 | E34: 0.09 | F34: 0.083 | G34: 0.08 | H34: 0.088 | I34: 0.102 | J34: 0.122 | K34: 0.196 | L34: 0.298 | M34: 0.297 | N34: 0.286 | O34: 0.283 | P34: 0.279 | Q34: 0.276
A35: 200000 | B35: =LN(A35) -> 12.206073 | C35: 0.093 | D35: 0.082 | E35: 0.07 | F35: 0.068 | G35: 0.062 | H35: 0.062 | I35: 0.063 | J35: 0.073 | K35: 0.12 | L35: 0.229 | M35: 0.279 | N35: 0.268 | O35: 0.268 | P35: 0.265 | Q35: 0.263
A36: 400000 | B36: =LN(A36) -> 12.89922 | C36: 0.079 | D36: 0.068 | E36: 0.056 | F36: 0.048 | G36: 0.048 | H36: 0.048 | I36: 0.051 | J36: 0.051 | K36: 0.068 | L36: 0.12 | M36: 0.271 | N36: 0.272 | O36: 0.272 | P36: 0.268 | Q36: 0.268

Sheet 5 Потери
A1: Потери давления на каждом элементе сети — режим пусконаладки: 3 поста по 1500 м³/ч
A2: Общая формула: Δp = ζ·p_д, p_д = ρw²/2 (динамическое давление), w = Q/F. Для воздуховода ζ = λ·l/d (трение), λ — по Альтшулю: λ = 0,11·(kэ/d + 68/Re)^0,25. Для тройников ζ отнесён к скорости в ОБЩЕМ (сборном) канале — поэтому для них w и p_д считаются по d_с и Q_с. Расходы постов (синие, колонка G в строках «зонт») — это решение сети из ядра при углах заслонок пусконаладки; Excel их не решает, а ПРОВЕРЯЕТ: сумма потерь по пути каждого поста должна равняться давлению вентилятора (лист 6). Расходы участков коллектора — сумма постов (закон сохранения массы).
A4: № | B4: Участок | C4: Элемент | D4: Тип | E4: d (d₁), м | F4: l, м | G4: Q, м³/ч | H4: Q_с, м³/ч (общий канал) | I4: Q_б, м³/ч (боковой поток) | J4: Параметр 1 | K4: Параметр 2 | L4: d расч., м | M4: w, м/с | N4: Re | O4: λ | P4: ζ | Q4: p_д, Па | R4: Δp, Па (Excel) | S4: Δp, Па (ядро) | T4: Разница, Па | U4: Формула ζ / пояснение | V4: Источник | W4: k_Re (отвод) / ζ₂ (диффузор) | X4: k_Δ (отвод)
A5: 1 | B5: post1 | C5: hood1 | D5: local | E5: 0.2 | G5: 1499.2931 | J5: 0.2 | L5: =E5 -> 0.2 | M5: =G5/3600/(PI()*L5^2/4) -> 13.256662 | N5: =M5*L5/'1 Исходные'!$D$7 -> 176051.28 | P5: =J5 -> 0.2 | Q5: ='1 Исходные'!$D$6*M5^2/2 -> 105.44345 | R5: =P5*Q5 -> 21.088689 | S5: 21.088689 | T5: =R5-S5 -> 7.3340392e-08 | U5: Вход через конический коллектор (раструб) α = 60°: ζ = 0,25 при l/D = 0,15 и 0,17 при l/D = 0,25 — принято 0,2 (параметр 1). Без раструба (острая кромка) — 0,5. | V5: Идельчик, 1992, диагр. 3-6, с. 127 [С] — сверено; геометрия [Д]
A6: 2 | B6: post1 | C6: branch1 | D6: duct | E6: 0.2 | F6: 6 | G6: =$G$5 -> 1499.2931 | L6: =E6 -> 0.2 | M6: =G6/3600/(PI()*L6^2/4) -> 13.256662 | N6: =M6*L6/'1 Исходные'!$D$7 -> 176051.28 | O6: =IF(N6<=2000,64/N6,IF(N6>=4000,0.11*('1 Исходные'!$D$10/E6+68/N6)^0.25,(1-(N6-2000)/2000)*64/2000+(N6-2000)/2000*0.11*('1 Исходные'!$D$10/E6+68/4000)^0.25)) -> 0.018979374 | P6: =O6*F6/E6 -> 0.56938122 | Q6: ='1 Исходные'!$D$6*M6^2/2 -> 105.44345 | R6: =P6*Q6 -> 60.037517 | S6: 60.037518 | T6: =R6-S6 -> -8.4423799e-07 | U6: Трение по длине: ζ = λ·l/d. λ: Re ≤ 2000 — 64/Re; Re ≥ 4000 — Альтшуль 0,11(kэ/d + 68/Re)^0,25; между — линейно (чтобы λ была непрерывной). | V6: Дарси–Вейсбах; Альтшуль А.Д., 1982 [С]
A7: 3 | B7: post1 | C7: bend90_1 | D7: bend | E7: 0.2 | G7: =$G$5 -> 1499.2931 | J7: 90 | K7: 1.5 | L7: =E7 -> 0.2 | M7: =G7/3600/(PI()*L7^2/4) -> 13.256662 | N7: =M7*L7/'1 Исходные'!$D$7 -> 176051.28 | O7: =IF(N7<=2000,64/N7,IF(N7>=4000,0.11*('1 Исходные'!$D$10/L7+68/N7)^0.25,(1-(N7-2000)/2000)*64/2000+(N7-2000)/2000*0.11*('1 Исходные'!$D$10/L7+68/4000)^0.25)) -> 0.018979374 | P7: =X7*W7*IF(J7>=180,1.4,INDEX('4 Таблицы'!$B$18:$B$28,MATCH(J7,'4 Таблицы'!$A$18:$A$28,1))+(J7-INDEX('4 Таблицы'!$A$18:$A$28,MATCH(J7,'4 Таблицы'!$A$18:$A$28,1)))*(INDEX('4 Таблицы'!$B$18:$B$28,MATCH(J7,'4 Таблицы'!$A$18:$A$28,1)+1)-INDEX('4 Таблицы'!$B$18:$B$28,MATCH(J7,'4 Таблицы'!$A$18:$A$28,1)))/(INDEX('4 Таблицы'!$A$18:$A$28,MATCH(J7,'4 Таблицы'!$A$18:$A$28,1)+1)-INDEX('4 Таблицы'!$A$18:$A$28,MATCH(J7,'4 Таблицы'!$A$18:$A$28,1))))*IF(K7<=1,0.21/K7^2.5,0.21/K7^0.5) -> 0.23941714 | Q7: ='1 Исходные'!$D$6*M7^2/2 -> 105.44345 | R7: =P7*Q7 -> 25.244968 | S7: 25.244969 | T7: =R7-S7 -> -5.1887951e-07 | U7: отвод 90°, R/D = 1,5. Стальной (шероховатый) воздуховод, п. 2 диагр. 6-1: ζ = k_Δ·k_Re·A₁·B₁. A₁ — по таблице (лист 4), B₁ = 0,21/(R/D)^2,5 при R/D ≤ 1, 0,21/(R/D)^0,5 при R/D > 1. k_Re = 1,3 − 0,29·ln(Re·10⁻⁵) при R/D > 0,7. k_Δ: Re 4·10⁴…2·10⁵ — λ_Δ/λ_гл (λ_гл = 1/(1,8 lg Re − 1,64)²), > 2·10⁵ — 1 + Δ̄·10³, сглажено по ln Re на границах [М]. Колонки W, X — k_Re, k_Δ. Параметр 1 = δ, °; 2 = R/D. | V7: Идельчик, 1992, диагр. 6-1, с. 277–278 [С] — сверено | W7: =IF(K7>0.7,1.3-0.29*LN(MAX(N7,10000)*0.00001),IF(K7>0.55,5.45/MAX(N7,10000)^0.131,1+4400/MAX(N7,10000))) -> 1.1359745 | X7: =IF(N7<=32000,1,IF(N7<50000,(1+MIN(1,MAX(0,LN(N7/32000)/LN(50000/32000)))*((O7*(1.8*LOG10(MAX(N7,4000))-1.64)^2)-1)),IF(N7<=160000,(O7*(1.8*LOG10(MAX(N7,4000))-1.64)^2),IF(N7<250000,((O7*(1.8*LOG10(MAX(N7,4000))-1.64)^2)+MIN(1,MAX(0,LN(N7/160000)/LN(250000/160000)))*((1+MIN('1 Исходные'!$D$10/L7,0.001)*1000)-(O7*(1.8*LOG10(MAX(N7,4000))-1.64)^2))),(1+MIN('1 Исходные'!$D$10/L7,0.001)*1000))))) -> 1.2291729
A8: 4 | B8: post1 | C8: bend45_1 | D8: bend | E8: 0.2 | G8: =$G$5 -> 1499.2931 | J8: 45 | K8: 1.5 | L8: =E8 -> 0.2 | M8: =G8/3600/(PI()*L8^2/4) -> 13.256662 | N8: =M8*L8/'1 Исходные'!$D$7 -> 176051.28 | O8: =IF(N8<=2000,64/N8,IF(N8>=4000,0.11*('1 Исходные'!$D$10/L8+68/N8)^0.25,(1-(N8-2000)/2000)*64/2000+(N8-2000)/2000*0.11*('1 Исходные'!$D$10/L8+68/4000)^0.25)) -> 0.018979374 | P8: =X8*W8*IF(J8>=180,1.4,INDEX('4 Таблицы'!$B$18:$B$28,MATCH(J8,'4 Таблицы'!$A$18:$A$28,1))+(J8-INDEX('4 Таблицы'!$A$18:$A$28,MATCH(J8,'4 Таблицы'!$A$18:$A$28,1)))*(INDEX('4 Таблицы'!$B$18:$B$28,MATCH(J8,'4 Таблицы'!$A$18:$A$28,1)+1)-INDEX('4 Таблицы'!$B$18:$B$28,MATCH(J8,'4 Таблицы'!$A$18:$A$28,1)))/(INDEX('4 Таблицы'!$A$18:$A$28,MATCH(J8,'4 Таблицы'!$A$18:$A$28,1)+1)-INDEX('4 Таблицы'!$A$18:$A$28,MATCH(J8,'4 Таблицы'!$A$18:$A$28,1))))*IF(K8<=1,0.21/K8^2.5,0.21/K8^0.5) -> 0.14365029 | Q8: ='1 Исходные'!$D$6*M8^2/2 -> 105.44345 | R8: =P8*Q8 -> 15.146981 | S8: 15.146981 | T8: =R8-S8 -> 8.8672294e-08 | U8: отвод 45°, R/D = 1,5. Стальной (шероховатый) воздуховод, п. 2 диагр. 6-1: ζ = k_Δ·k_Re·A₁·B₁. A₁ — по таблице (лист 4), B₁ = 0,21/(R/D)^2,5 при R/D ≤ 1, 0,21/(R/D)^0,5 при R/D > 1. k_Re = 1,3 − 0,29·ln(Re·10⁻⁵) при R/D > 0,7. k_Δ: Re 4·10⁴…2·10⁵ — λ_Δ/λ_гл (λ_гл = 1/(1,8 lg Re − 1,64)²), > 2·10⁵ — 1 + Δ̄·10³, сглажено по ln Re на границах [М]. Колонки W, X — k_Re, k_Δ. Параметр 1 = δ, °; 2 = R/D. | V8: Идельчик, 1992, диагр. 6-1, с. 277–278 [С] — сверено | W8: =IF(K8>0.7,1.3-0.29*LN(MAX(N8,10000)*0.00001),IF(K8>0.55,5.45/MAX(N8,10000)^0.131,1+4400/MAX(N8,10000))) -> 1.1359745 | X8: =IF(N8<=32000,1,IF(N8<50000,(1+MIN(1,MAX(0,LN(N8/32000)/LN(50000/32000)))*((O8*(1.8*LOG10(MAX(N8,4000))-1.64)^2)-1)),IF(N8<=160000,(O8*(1.8*LOG10(MAX(N8,4000))-1.64)^2),IF(N8<250000,((O8*(1.8*LOG10(MAX(N8,4000))-1.64)^2)+MIN(1,MAX(0,LN(N8/160000)/LN(250000/160000)))*((1+MIN('1 Исходные'!$D$10/L8,0.001)*1000)-(O8*(1.8*LOG10(MAX(N8,4000))-1.64)^2))),(1+MIN('1 Исходные'!$D$10/L8,0.001)*1000))))) -> 1.2291729
A9: 5 | B9: post1 | C9: damper1 | D9: damper | E9: 0.2 | G9: =$G$5 -> 1499.2931 | J9: 0.121757 | L9: =E9 -> 0.2 | M9: =G9/3600/(PI()*L9^2/4) -> 13.256662 | N9: =M9*L9/'1 Исходные'!$D$7 -> 176051.28 | P9: =IF(J9>=90,10000,EXP(LN(INDEX('4 Таблицы'!$B$5:$B$13,MATCH(J9,'4 Таблицы'!$A$5:$A$13,1)))+(J9-INDEX('4 Таблицы'!$A$5:$A$13,MATCH(J9,'4 Таблицы'!$A$5:$A$13,1)))/(INDEX('4 Таблицы'!$A$5:$A$13,MATCH(J9,'4 Таблицы'!$A$5:$A$13,1)+1)-INDEX('4 Таблицы'!$A$5:$A$13,MATCH(J9,'4 Таблицы'!$A$5:$A$13,1)))*(LN(INDEX('4 Таблицы'!$B$5:$B$13,MATCH(J9,'4 Таблицы'!$A$5:$A$13,1)+1))-LN(INDEX('4 Таблицы'!$B$5:$B$13,MATCH(J9,'4 Таблицы'!$A$5:$A$13,1)))))) -> 0.20234039 | Q9: ='1 Исходные'!$D$6*M9^2/2 -> 105.44345 | R9: =P9*Q9 -> 21.335468 | S9: 21.335469 | T9: =R9-S9 -> -9.4901543e-07 | U9: Дроссель-клапан: ζ(α) по таблице листа «4 Таблицы» с интерполяцией по ln ζ. Параметр 1 = угол α, °. | V9: Идельчик, 1992, диагр. 9-17, кривая 2 [С] — сверено
A10: 6 | B10: post1 | C10: bend_end | D10: bend | E10: 0.2 | G10: =$G$5 -> 1499.2931 | J10: 90 | K10: 1 | L10: =E10 -> 0.2 | M10: =G10/3600/(PI()*L10^2/4) -> 13.256662 | N10: =M10*L10/'1 Исходные'!$D$7 -> 176051.28 | O10: =IF(N10<=2000,64/N10,IF(N10>=4000,0.11*('1 Исходные'!$D$10/L10+68/N10)^0.25,(1-(N10-2000)/2000)*64/2000+(N10-2000)/2000*0.11*('1 Исходные'!$D$10/L10+68/4000)^0.25)) -> 0.018979374 | P10: =X10*W10*IF(J10>=180,1.4,INDEX('4 Таблицы'!$B$18:$B$28,MATCH(J10,'4 Таблицы'!$A$18:$A$28,1))+(J10-INDEX('4 Таблицы'!$A$18:$A$28,MATCH(J10,'4 Таблицы'!$A$18:$A$28,1)))*(INDEX('4 Таблицы'!$B$18:$B$28,MATCH(J10,'4 Таблицы'!$A$18:$A$28,1)+1)-INDEX('4 Таблицы'!$B$18:$B$28,MATCH(J10,'4 Таблицы'!$A$18:$A$28,1)))/(INDEX('4 Таблицы'!$A$18:$A$28,MATCH(J10,'4 Таблицы'!$A$18:$A$28,1)+1)-INDEX('4 Таблицы'!$A$18:$A$28,MATCH(J10,'4 Таблицы'!$A$18:$A$28,1))))*IF(K10<=1,0.21/K10^2.5,0.21/K10^0.5) -> 0.29322492 | Q10: ='1 Исходные'!$D$6*M10^2/2 -> 105.44345 | R10: =P10*Q10 -> 30.918646 | S10: 30.918646 | T10: =R10-S10 -> -3.2430536e-07 | U10: отвод 90° в торец коллектора. Стальной (шероховатый) воздуховод, п. 2 диагр. 6-1: ζ = k_Δ·k_Re·A₁·B₁. A₁ — по таблице (лист 4), B₁ = 0,21/(R/D)^2,5 при R/D ≤ 1, 0,21/(R/D)^0,5 при R/D > 1. k_Re = 1,3 − 0,29·ln(Re·10⁻⁵) при R/D > 0,7. k_Δ: Re 4·10⁴…2·10⁵ — λ_Δ/λ_гл (λ_гл = 1/(1,8 lg Re − 1,64)²), > 2·10⁵ — 1 + Δ̄·10³, сглажено по ln Re на границах [М]. Колонки W, X — k_Re, k_Δ. Параметр 1 = δ, °; 2 = R/D. | V10: Идельчик, 1992, диагр. 6-1, с. 277–278 [С] — сверено | W10: =IF(K10>0.7,1.3-0.29*LN(MAX(N10,10000)*0.00001),IF(K10>0.55,5.45/MAX(N10,10000)^0.131,1+4400/MAX(N10,10000))) -> 1.1359745 | X10: =IF(N10<=32000,1,IF(N10<50000,(1+MIN(1,MAX(0,LN(N10/32000)/LN(50000/32000)))*((O10*(1.8*LOG10(MAX(N10,4000))-1.64)^2)-1)),IF(N10<=160000,(O10*(1.8*LOG10(MAX(N10,4000))-1.64)^2),IF(N10<250000,((O10*(1.8*LOG10(MAX(N10,4000))-1.64)^2)+MIN(1,MAX(0,LN(N10/160000)/LN(250000/160000)))*((1+MIN('1 Исходные'!$D$10/L10,0.001)*1000)-(O10*(1.8*LOG10(MAX(N10,4000))-1.64)^2))),(1+MIN('1 Исходные'!$D$10/L10,0.001)*1000))))) -> 1.2291729
A11: 7 | B11: post1 | C11: trans1 | D11: diffuser | E11: 0.2 | G11: =$G$5 -> 1499.2931 | J11: 0.25 | K11: 15 | L11: =E11 -> 0.2 | M11: =G11/3600/(PI()*L11^2/4) -> 13.256662 | N11: =M11*L11/'1 Исходные'!$D$7 -> 176051.28 | O11: =IF(N11<=2000,64/N11,IF(N11>=4000,0.11*('1 Исходные'!$D$10/L11+68/N11)^0.25,(1-(N11-2000)/2000)*64/2000+(N11-2000)/2000*0.11*('1 Исходные'!$D$10/L11+68/4000)^0.25)) -> 0.018979374 | P11: =MAX(0,W11-(O11/(8*SIN(RADIANS(K11/2)))*(1-1/(2)^2)))*((1-1/((J11/E11)^2))/0.5)^1.92+(O11/(8*SIN(RADIANS(K11/2)))*(1-1/(((J11/E11)^2))^2)) -> 0.043974788 | Q11: ='1 Исходные'!$D$6*M11^2/2 -> 105.44345 | R11: =P11*Q11 -> 4.6368532 | S11: 4.636853 | T11: =R11-S11 -> 1.5679481e-07 | U11: Переход на больший диаметр (диффузор), к скорости в узком сечении d₁. n = (d₂/d₁)². ζ₂ — таблица при n = 2 (лист 4) по α и Re (интерполяция по α и ln Re); пересчёт на n по формулам Идельчика (5-6), (5-7): ζ = (ζ₂ − ζ_тр(2))·((1 − 1/n)/0,5)^1,92 + ζ_тр(n), ζ_тр = λ/(8 sin(α/2))·(1 − 1/n²) [М]. Колонка W — ζ₂. Параметр 1 = d₂, м; 2 = α, °. | V11: Идельчик, 1992, диагр. 5-2, с. 211; ф. (5-6), (5-7), с. 192–193 [С] — сверено | W11: =(INDEX(OFFSET('4 Таблицы'!$C$33,MIN(MATCH(LN(MIN(MAX(N11,50000),400000)),'4 Таблицы'!$B$33:$B$36,1),3)-1,0,1,15),1,MIN(MATCH(K11,'4 Таблицы'!$C$32:$Q$32,1),14))+(K11-INDEX('4 Таблицы'!$C$32:$Q$32,1,MIN(MATCH(K11,'4 Таблицы'!$C$32:$Q$32,1),14)))*(INDEX(OFFSET('4 Таблицы'!$C$33,MIN(MATCH(LN(MIN(MAX(N11,50000),400000)),'4 Таблицы'!$B$33:$B$36,1),3)-1,0,1,15),1,MIN(MATCH(K11,'4 Таблицы'!$C$32:$Q$32,1),14)+1)-INDEX(OFFSET('4 Таблицы'!$C$33,MIN(MATCH(LN(MIN(MAX(N11,50000),400000)),'4 Таблицы'!$B$33:$B$36,1),3)-1,0,1,15),1,MIN(MATCH(K11,'4 Таблицы'!$C$32:$Q$32,1),14)))/(INDEX('4 Таблицы'!$C$32:$Q$32,1,MIN(MATCH(K11,'4 Таблицы'!$C$32:$Q$32,1),14)+1)-INDEX('4 Таблицы'!$C$32:$Q$32,1,MIN(MATCH(K11,'4 Таблицы'!$C$32:$Q$32,1),14))))+(LN(MIN(MAX(N11,50000),400000))-INDEX('4 Таблицы'!$B$33:$B$36,MIN(MATCH(LN(MIN(MAX(N11,50000),400000)),'4 Таблицы'!$B$33:$B$36,1),3)))/(INDEX('4 Таблицы'!$B$33:$B$36,MIN(MATCH(LN(MIN(MAX(N11,50000),400000)),'4 Таблицы'!$B$33:$B$36,1),3)+1)-INDEX('4 Таблицы'!$B$33:$B$36,MIN(MATCH(LN(MIN(MAX(N11,50000),400000)),'4 Таблицы'!$B$33:$B$36,1),3)))*((INDEX(OFFSET('4 Таблицы'!$C$33,MIN(MATCH(LN(MIN(MAX(N11,50000),400000)),'4 Таблицы'!$B$33:$B$36,1),3),0,1,15),1,MIN(MATCH(K11,'4 Таблицы'!$C$32:$Q$32,1),14))+(K11-INDEX('4 Таблицы'!$C$32:$Q$32,1,MIN(MATCH(K11,'4 Таблицы'!$C$32:$Q$32,1),14)))*(INDEX(OFFSET('4 Таблицы'!$C$33,MIN(MATCH(LN(MIN(MAX(N11,50000),400000)),'4 Таблицы'!$B$33:$B$36,1),3),0,1,15),1,MIN(MATCH(K11,'4 Таблицы'!$C$32:$Q$32,1),14)+1)-INDEX(OFFSET('4 Таблицы'!$C$33,MIN(MATCH(LN(MIN(MAX(N11,50000),400000)),'4 Таблицы'!$B$33:$B$36,1),3),0,1,15),1,MIN(MATCH(K11,'4 Таблицы'!$C$32:$Q$32,1),14)))/(INDEX('4 Таблицы'!$C$32:$Q$32,1,MIN(MATCH(K11,'4 Таблицы'!$C$32:$Q$32,1),14)+1)-INDEX('4 Таблицы'!$C$32:$Q$32,1,MIN(MATCH(K11,'4 Таблицы'!$C$32:$Q$32,1),14))))-(INDEX(OFFSET('4 Таблицы'!$C$33,MIN(MATCH(LN(MIN(MAX(N11,50000),400000)),'4 Таблицы'!$B$33:$B$36,1),3)-1,0,1,15),1,MIN(MATCH(K11,'4 Таблицы'!$C$32:$Q$32,1),14))+(K11-INDEX('4 Таблицы'!$C$32:$Q$32,1,MIN(MATCH(K11,'4 Таблицы'!$C$32:$Q$32,1),14)))*(INDEX(OFFSET('4 Таблицы'!$C$33,MIN(MATCH(LN(MIN(MAX(N11,50000),400000)),'4 Таблицы'!$B$33:$B$36,1),3)-1,0,1,15),1,MIN(MATCH(K11,'4 Таблицы'!$C$32:$Q$32,1),14)+1)-INDEX(OFFSET('4 Таблицы'!$C$33,MIN(MATCH(LN(MIN(MAX(N11,50000),400000)),'4 Таблицы'!$B$33:$B$36,1),3)-1,0,1,15),1,MIN(MATCH(K11,'4 Таблицы'!$C$32:$Q$32,1),14)))/(INDEX('4 Таблицы'!$C$32:$Q$32,1,MIN(MATCH(K11,'4 Таблицы'!$C$32:$Q$32,1),14)+1)-INDEX('4 Таблицы'!$C$32:$Q$32,1,MIN(MATCH(K11,'4 Таблицы'!$C$32:$Q$32,1),14))))) -> 0.076096188
A12: 8 | B12: c1 | C12: c1 | D12: duct | E12: 0.25 | F12: 5 | G12: =$G$5 -> 1499.2931 | L12: =E12 -> 0.25 | M12: =G12/3600/(PI()*L12^2/4) -> 8.4842634 | N12: =M12*L12/'1 Исходные'!$D$7 -> 140841.03 | O12: =IF(N12<=2000,64/N12,IF(N12>=4000,0.11*('1 Исходные'!$D$10/E12+68/N12)^0.25,(1-(N12-2000)/2000)*64/2000+(N12-2000)/2000*0.11*('1 Исходные'!$D$10/E12+68/4000)^0.25)) -> 0.018960945 | P12: =O12*F12/E12 -> 0.37921889 | Q12: ='1 Исходные'!$D$6*M12^2/2 -> 43.189635 | R12: =P12*Q12 -> 16.378326 | S12: 16.378326 | T12: =R12-S12 -> -3.0373162e-07 | U12: Трение по длине: ζ = λ·l/d. λ: Re ≤ 2000 — 64/Re; Re ≥ 4000 — Альтшуль 0,11(kэ/d + 68/Re)^0,25; между — линейно (чтобы λ была непрерывной). | V12: Дарси–Вейсбах; Альтшуль А.Д., 1982 [С]
A13: 9 | B13: c1 | C13: trans_c1 | D13: diffuser | E13: 0.25 | G13: =$G$12 -> 1499.2931 | J13: 0.315 | K13: 15 | L13: =E13 -> 0.25 | M13: =G13/3600/(PI()*L13^2/4) -> 8.4842634 | N13: =M13*L13/'1 Исходные'!$D$7 -> 140841.03 | O13: =IF(N13<=2000,64/N13,IF(N13>=4000,0.11*('1 Исходные'!$D$10/L13+68/N13)^0.25,(1-(N13-2000)/2000)*64/2000+(N13-2000)/2000*0.11*('1 Исходные'!$D$10/L13+68/4000)^0.25)) -> 0.018960945 | P13: =MAX(0,W13-(O13/(8*SIN(RADIANS(K13/2)))*(1-1/(2)^2)))*((1-1/((J13/E13)^2))/0.5)^1.92+(O13/(8*SIN(RADIANS(K13/2)))*(1-1/(((J13/E13)^2))^2)) -> 0.053972952 | Q13: ='1 Исходные'!$D$6*M13^2/2 -> 43.189635 | R13: =P13*Q13 -> 2.3310721 | S13: 2.331072 | T13: =R13-S13 -> 1.1452692e-07 | U13: Переход на больший диаметр (диффузор), к скорости в узком сечении d₁. n = (d₂/d₁)². ζ₂ — таблица при n = 2 (лист 4) по α и Re (интерполяция по α и ln Re); пересчёт на n по формулам Идельчика (5-6), (5-7): ζ = (ζ₂ − ζ_тр(2))·((1 − 1/n)/0,5)^1,92 + ζ_тр(n), ζ_тр = λ/(8 sin(α/2))·(1 − 1/n²) [М]. Колонка W — ζ₂. Параметр 1 = d₂, м; 2 = α, °. | V13: Идельчик, 1992, диагр. 5-2, с. 211; ф. (5-6), (5-7), с. 192–193 [С] — сверено | W13: =(INDEX(OFFSET('4 Таблицы'!$C$33,MIN(MATCH(LN(MIN(MAX(N13,50000),400000)),'4 Таблицы'!$B$33:$B$36,1),3)-1,0,1,15),1,MIN(MATCH(K13,'4 Таблицы'!$C$32:$Q$32,1),14))+(K13-INDEX('4 Таблицы'!$C$32:$Q$32,1,MIN(MATCH(K13,'4 Таблицы'!$C$32:$Q$32,1),14)))*(INDEX(OFFSET('4 Таблицы'!$C$33,MIN(MATCH(LN(MIN(MAX(N13,50000),400000)),'4 Таблицы'!$B$33:$B$36,1),3)-1,0,1,15),1,MIN(MATCH(K13,'4 Таблицы'!$C$32:$Q$32,1),14)+1)-INDEX(OFFSET('4 Таблицы'!$C$33,MIN(MATCH(LN(MIN(MAX(N13,50000),400000)),'4 Таблицы'!$B$33:$B$36,1),3)-1,0,1,15),1,MIN(MATCH(K13,'4 Таблицы'!$C$32:$Q$32,1),14)))/(INDEX('4 Таблицы'!$C$32:$Q$32,1,MIN(MATCH(K13,'4 Таблицы'!$C$32:$Q$32,1),14)+1)-INDEX('4 Таблицы'!$C$32:$Q$32,1,MIN(MATCH(K13,'4 Таблицы'!$C$32:$Q$32,1),14))))+(LN(MIN(MAX(N13,50000),400000))-INDEX('4 Таблицы'!$B$33:$B$36,MIN(MATCH(LN(MIN(MAX(N13,50000),400000)),'4 Таблицы'!$B$33:$B$36,1),3)))/(INDEX('4 Таблицы'!$B$33:$B$36,MIN(MATCH(LN(MIN(MAX(N13,50000),400000)),'4 Таблицы'!$B$33:$B$36,1),3)+1)-INDEX('4 Таблицы'!$B$33:$B$36,MIN(MATCH(LN(MIN(MAX(N13,50000),400000)),'4 Таблицы'!$B$33:$B$36,1),3)))*((INDEX(OFFSET('4 Таблицы'!$C$33,MIN(MATCH(LN(MIN(MAX(N13,50000),400000)),'4 Таблицы'!$B$33:$B$36,1),3),0,1,15),1,MIN(MATCH(K13,'4 Таблицы'!$C$32:$Q$32,1),14))+(K13-INDEX('4 Таблицы'!$C$32:$Q$32,1,MIN(MATCH(K13,'4 Таблицы'!$C$32:$Q$32,1),14)))*(INDEX(OFFSET('4 Таблицы'!$C$33,MIN(MATCH(LN(MIN(MAX(N13,50000),400000)),'4 Таблицы'!$B$33:$B$36,1),3),0,1,15),1,MIN(MATCH(K13,'4 Таблицы'!$C$32:$Q$32,1),14)+1)-INDEX(OFFSET('4 Таблицы'!$C$33,MIN(MATCH(LN(MIN(MAX(N13,50000),400000)),'4 Таблицы'!$B$33:$B$36,1),3),0,1,15),1,MIN(MATCH(K13,'4 Таблицы'!$C$32:$Q$32,1),14)))/(INDEX('4 Таблицы'!$C$32:$Q$32,1,MIN(MATCH(K13,'4 Таблицы'!$C$32:$Q$32,1),14)+1)-INDEX('4 Таблицы'!$C$32:$Q$32,1,MIN(MATCH(K13,'4 Таблицы'!$C$32:$Q$32,1),14))))-(INDEX(OFFSET('4 Таблицы'!$C$33,MIN(MATCH(LN(MIN(MAX(N13,50000),400000)),'4 Таблицы'!$B$33:$B$36,1),3)-1,0,1,15),1,MIN(MATCH(K13,'4 Таблицы'!$C$32:$Q$32,1),14))+(K13-INDEX('4 Таблицы'!$C$32:$Q$32,1,MIN(MATCH(K13,'4 Таблицы'!$C$32:$Q$32,1),14)))*(INDEX(OFFSET('4 Таблицы'!$C$33,MIN(MATCH(LN(MIN(MAX(N13,50000),400000)),'4 Таблицы'!$B$33:$B$36,1),3)-1,0,1,15),1,MIN(MATCH(K13,'4 Таблицы'!$C$32:$Q$32,1),14)+1)-INDEX(OFFSET('4 Таблицы'!$C$33,MIN(MATCH(LN(MIN(MAX(N13,50000),400000)),'4 Таблицы'!$B$33:$B$36,1),3)-1,0,1,15),1,MIN(MATCH(K13,'4 Таблицы'!$C$32:$Q$32,1),14)))/(INDEX('4 Таблицы'!$C$32:$Q$32,1,MIN(MATCH(K13,'4 Таблицы'!$C$32:$Q$32,1),14)+1)-INDEX('4 Таблицы'!$C$32:$Q$32,1,MIN(MATCH(K13,'4 Таблицы'!$C$32:$Q$32,1),14))))) -> 0.090261024
A14: 10 | B14: c1 | C14: teeP2 | D14: teeStraight | E14: 0.315 | G14: =$G$12 -> 1499.2931 | H14: =G14+I14 -> 2998.7509 | I14: =$G$15 -> 1499.4578 | L14: =E14 -> 0.315 | M14: =H14/3600/(PI()*L14^2/4) -> 10.68875 | N14: =M14*L14/'1 Исходные'!$D$7 -> 223569.46 | P14: =1.55*(I14/H14)-(I14/H14)^2 -> 0.5250151 | Q14: ='1 Исходные'!$D$6*M14^2/2 -> 68.54962 | R14: =P14*Q14 -> 35.989586 | S14: 35.989587 | T14: =R14-S14 -> -1.031613e-06 | U14: Тройник на слияние, проход. r = Q_б/Q_с (Q_б — боковой поток, колонка I). ζ = 1,55·r − r², к скорости в общем канале (d = d_с). | V14: Идельчик, 1992, диагр. 7-4, с. 346 [С] — сверено
A15: 11 | B15: post2 | C15: hood2 | D15: local | E15: 0.2 | G15: 1499.4578 | J15: 0.2 | L15: =E15 -> 0.2 | M15: =G15/3600/(PI()*L15^2/4) -> 13.258118 | N15: =M15*L15/'1 Исходные'!$D$7 -> 176070.62 | P15: =J15 -> 0.2 | Q15: ='1 Исходные'!$D$6*M15^2/2 -> 105.46661 | R15: =P15*Q15 -> 21.093323 | S15: 21.093323 | T15: =R15-S15 -> -4.1255241e-07 | U15: Вход через конический коллектор (раструб) α = 60°: ζ = 0,25 при l/D = 0,15 и 0,17 при l/D = 0,25 — принято 0,2 (параметр 1). Без раструба (острая кромка) — 0,5. | V15: Идельчик, 1992, диагр. 3-6, с. 127 [С] — сверено; геометрия [Д]
A16: 12 | B16: post2 | C16: branch2 | D16: duct | E16: 0.2 | F16: 6 | G16: =$G$15 -> 1499.4578 | L16: =E16 -> 0.2 | M16: =G16/3600/(PI()*L16^2/4) -> 13.258118 | N16: =M16*L16/'1 Исходные'!$D$7 -> 176070.62 | O16: =IF(N16<=2000,64/N16,IF(N16>=4000,0.11*('1 Исходные'!$D$10/E16+68/N16)^0.25,(1-(N16-2000)/2000)*64/2000+(N16-2000)/2000*0.11*('1 Исходные'!$D$10/E16+68/4000)^0.25)) -> 0.018979147 | P16: =O16*F16/E16 -> 0.5693744 | Q16: ='1 Исходные'!$D$6*M16^2/2 -> 105.46661 | R16: =P16*Q16 -> 60.04999 | S16: 60.049992 | T16: =R16-S16 -> -2.3491679e-06 | U16: Трение по длине: ζ = λ·l/d. λ: Re ≤ 2000 — 64/Re; Re ≥ 4000 — Альтшуль 0,11(kэ/d + 68/Re)^0,25; между — линейно (чтобы λ была непрерывной). | V16: Дарси–Вейсбах; Альтшуль А.Д., 1982 [С]
A17: 13 | B17: post2 | C17: bend90_2 | D17: bend | E17: 0.2 | G17: =$G$15 -> 1499.4578 | J17: 90 | K17: 1.5 | L17: =E17 -> 0.2 | M17: =G17/3600/(PI()*L17^2/4) -> 13.258118 | N17: =M17*L17/'1 Исходные'!$D$7 -> 176070.62 | O17: =IF(N17<=2000,64/N17,IF(N17>=4000,0.11*('1 Исходные'!$D$10/L17+68/N17)^0.25,(1-(N17-2000)/2000)*64/2000+(N17-2000)/2000*0.11*('1 Исходные'!$D$10/L17+68/4000)^0.25)) -> 0.018979147 | P17: =X17*W17*IF(J17>=180,1.4,INDEX('4 Таблицы'!$B$18:$B$28,MATCH(J17,'4 Таблицы'!$A$18:$A$28,1))+(J17-INDEX('4 Таблицы'!$A$18:$A$28,MATCH(J17,'4 Таблицы'!$A$18:$A$28,1)))*(INDEX('4 Таблицы'!$B$18:$B$28,MATCH(J17,'4 Таблицы'!$A$18:$A$28,1)+1)-INDEX('4 Таблицы'!$B$18:$B$28,MATCH(J17,'4 Таблицы'!$A$18:$A$28,1)))/(INDEX('4 Таблицы'!$A$18:$A$28,MATCH(J17,'4 Таблицы'!$A$18:$A$28,1)+1)-INDEX('4 Таблицы'!$A$18:$A$28,MATCH(J17,'4 Таблицы'!$A$18:$A$28,1))))*IF(K17<=1,0.21/K17^2.5,0.21/K17^0.5) -> 0.23942873 | Q17: ='1 Исходные'!$D$6*M17^2/2 -> 105.46661 | R17: =P17*Q17 -> 25.251737 | S17: 25.251738 | T17: =R17-S17 -> -1.0194178e-06 | U17: отвод 90°, R/D = 1,5. Стальной (шероховатый) воздуховод, п. 2 диагр. 6-1: ζ = k_Δ·k_Re·A₁·B₁. A₁ — по таблице (лист 4), B₁ = 0,21/(R/D)^2,5 при R/D ≤ 1, 0,21/(R/D)^0,5 при R/D > 1. k_Re = 1,3 − 0,29·ln(Re·10⁻⁵) при R/D > 0,7. k_Δ: Re 4·10⁴…2·10⁵ — λ_Δ/λ_гл (λ_гл = 1/(1,8 lg Re − 1,64)²), > 2·10⁵ — 1 + Δ̄·10³, сглажено по ln Re на границах [М]. Колонки W, X — k_Re, k_Δ. Параметр 1 = δ, °; 2 = R/D. | V17: Идельчик, 1992, диагр. 6-1, с. 277–278 [С] — сверено | W17: =IF(K17>0.7,1.3-0.29*LN(MAX(N17,10000)*0.00001),IF(K17>0.55,5.45/MAX(N17,10000)^0.131,1+4400/MAX(N17,10000))) -> 1.1359427 | X17: =IF(N17<=32000,1,IF(N17<50000,(1+MIN(1,MAX(0,LN(N17/32000)/LN(50000/32000)))*((O17*(1.8*LOG10(MAX(N17,4000))-1.64)^2)-1)),IF(N17<=160000,(O17*(1.8*LOG10(MAX(N17,4000))-1.64)^2),IF(N17<250000,((O17*(1.8*LOG10(MAX(N17,4000))-1.64)^2)+MIN(1,MAX(0,LN(N17/160000)/LN(250000/160000)))*((1+MIN('1 Исходные'!$D$10/L17,0.001)*1000)-(O17*(1.8*LOG10(MAX(N17,4000))-1.64)^2))),(1+MIN('1 Исходные'!$D$10/L17,0.001)*1000))))) -> 1.2292669
A18: 14 | B18: post2 | C18: bend45_2 | D18: bend | E18: 0.2 | G18: =$G$15 -> 1499.4578 | J18: 45 | K18: 1.5 | L18: =E18 -> 0.2 | M18: =G18/3600/(PI()*L18^2/4) -> 13.258118 | N18: =M18*L18/'1 Исходные'!$D$7 -> 176070.62 | O18: =IF(N18<=2000,64/N18,IF(N18>=4000,0.11*('1 Исходные'!$D$10/L18+68/N18)^0.25,(1-(N18-2000)/2000)*64/2000+(N18-2000)/2000*0.11*('1 Исходные'!$D$10/L18+68/4000)^0.25)) -> 0.018979147 | P18: =X18*W18*IF(J18>=180,1.4,INDEX('4 Таблицы'!$B$18:$B$28,MATCH(J18,'4 Таблицы'!$A$18:$A$28,1))+(J18-INDEX('4 Таблицы'!$A$18:$A$28,MATCH(J18,'4 Таблицы'!$A$18:$A$28,1)))*(INDEX('4 Таблицы'!$B$18:$B$28,MATCH(J18,'4 Таблицы'!$A$18:$A$28,1)+1)-INDEX('4 Таблицы'!$B$18:$B$28,MATCH(J18,'4 Таблицы'!$A$18:$A$28,1)))/(INDEX('4 Таблицы'!$A$18:$A$28,MATCH(J18,'4 Таблицы'!$A$18:$A$28,1)+1)-INDEX('4 Таблицы'!$A$18:$A$28,MATCH(J18,'4 Таблицы'!$A$18:$A$28,1))))*IF(K18<=1,0.21/K18^2.5,0.21/K18^0.5) -> 0.14365724 | Q18: ='1 Исходные'!$D$6*M18^2/2 -> 105.46661 | R18: =P18*Q18 -> 15.151042 | S18: 15.151043 | T18: =R18-S18 -> -8.1165066e-07 | U18: отвод 45°, R/D = 1,5. Стальной (шероховатый) воздуховод, п. 2 диагр. 6-1: ζ = k_Δ·k_Re·A₁·B₁. A₁ — по таблице (лист 4), B₁ = 0,21/(R/D)^2,5 при R/D ≤ 1, 0,21/(R/D)^0,5 при R/D > 1. k_Re = 1,3 − 0,29·ln(Re·10⁻⁵) при R/D > 0,7. k_Δ: Re 4·10⁴…2·10⁵ — λ_Δ/λ_гл (λ_гл = 1/(1,8 lg Re − 1,64)²), > 2·10⁵ — 1 + Δ̄·10³, сглажено по ln Re на границах [М]. Колонки W, X — k_Re, k_Δ. Параметр 1 = δ, °; 2 = R/D. | V18: Идельчик, 1992, диагр. 6-1, с. 277–278 [С] — сверено | W18: =IF(K18>0.7,1.3-0.29*LN(MAX(N18,10000)*0.00001),IF(K18>0.55,5.45/MAX(N18,10000)^0.131,1+4400/MAX(N18,10000))) -> 1.1359427 | X18: =IF(N18<=32000,1,IF(N18<50000,(1+MIN(1,MAX(0,LN(N18/32000)/LN(50000/32000)))*((O18*(1.8*LOG10(MAX(N18,4000))-1.64)^2)-1)),IF(N18<=160000,(O18*(1.8*LOG10(MAX(N18,4000))-1.64)^2),IF(N18<250000,((O18*(1.8*LOG10(MAX(N18,4000))-1.64)^2)+MIN(1,MAX(0,LN(N18/160000)/LN(250000/160000)))*((1+MIN('1 Исходные'!$D$10/L18,0.001)*1000)-(O18*(1.8*LOG10(MAX(N18,4000))-1.64)^2))),(1+MIN('1 Исходные'!$D$10/L18,0.001)*1000))))) -> 1.2292669
A19: 15 | B19: post2 | C19: damper2 | D19: damper | E19: 0.2 | G19: =$G$15 -> 1499.4578 | J19: 5.21025 | L19: =E19 -> 0.2 | M19: =G19/3600/(PI()*L19^2/4) -> 13.258118 | N19: =M19*L19/'1 Исходные'!$D$7 -> 176070.62 | P19: =IF(J19>=90,10000,EXP(LN(INDEX('4 Таблицы'!$B$5:$B$13,MATCH(J19,'4 Таблицы'!$A$5:$A$13,1)))+(J19-INDEX('4 Таблицы'!$A$5:$A$13,MATCH(J19,'4 Таблицы'!$A$5:$A$13,1)))/(INDEX('4 Таблицы'!$A$5:$A$13,MATCH(J19,'4 Таблицы'!$A$5:$A$13,1)+1)-INDEX('4 Таблицы'!$A$5:$A$13,MATCH(J19,'4 Таблицы'!$A$5:$A$13,1)))*(LN(INDEX('4 Таблицы'!$B$5:$B$13,MATCH(J19,'4 Таблицы'!$A$5:$A$13,1)+1))-LN(INDEX('4 Таблицы'!$B$5:$B$13,MATCH(J19,'4 Таблицы'!$A$5:$A$13,1)))))) -> 0.32903454 | Q19: ='1 Исходные'!$D$6*M19^2/2 -> 105.46661 | R19: =P19*Q19 -> 34.702158 | S19: 34.702159 | T19: =R19-S19 -> -9.7324045e-07 | U19: Дроссель-клапан: ζ(α) по таблице листа «4 Таблицы» с интерполяцией по ln ζ. Параметр 1 = угол α, °. | V19: Идельчик, 1992, диагр. 9-17, кривая 2 [С] — сверено
A20: 16 | B20: post2 | C20: tee2 | D20: teeSide | E20: 0.2 | G20: =$G$15 -> 1499.4578 | H20: =$G$21 -> 2998.7509 | J20: 0.315 | L20: =J20 -> 0.315 | M20: =H20/3600/(PI()*L20^2/4) -> 10.68875 | N20: =M20*L20/'1 Исходные'!$D$7 -> 223569.46 | P20: =IF((E20/J20)^2<=0.35,1,MAX(0.9*(1-(G20/H20)),0.55))*(1+((G20/H20)*(J20/E20)^2)^2-2*(1-(G20/H20))^2) -> 1.1212295 | Q20: ='1 Исходные'!$D$6*M20^2/2 -> 68.54962 | R20: =P20*Q20 -> 76.859853 | S20: 76.859856 | T20: =R20-S20 -> -2.6390347e-06 | U20: Тройник на слияние, боковой вход. r = Q_б/Q_с. ζ = A·[1 + (r·F_с/F_б)² − 2(1 − r)²], к скорости в общем канале d_с (параметр 1). A: F_б/F_с ≤ 0,35 → 1; иначе max(0,9(1 − r); 0,55). Может быть < 0 (эжекция) — это физика. | V20: Идельчик, 1992, диагр. 7-4, с. 346; A — табл. 7-1, с. 335 [С] — сверено
A21: 17 | B21: c2 | C21: c2 | D21: duct | E21: 0.315 | F21: 5 | G21: =$G$12+$G$15 -> 2998.7509 | L21: =E21 -> 0.315 | M21: =G21/3600/(PI()*L21^2/4) -> 10.68875 | N21: =M21*L21/'1 Исходные'!$D$7 -> 223569.46 | O21: =IF(N21<=2000,64/N21,IF(N21>=4000,0.11*('1 Исходные'!$D$10/E21+68/N21)^0.25,(1-(N21-2000)/2000)*64/2000+(N21-2000)/2000*0.11*('1 Исходные'!$D$10/E21+68/4000)^0.25)) -> 0.017368939 | P21: =O21*F21/E21 -> 0.27569745 | Q21: ='1 Исходные'!$D$6*M21^2/2 -> 68.54962 | R21: =P21*Q21 -> 18.898955 | S21: 18.898956 | T21: =R21-S21 -> -7.8486367e-07 | U21: Трение по длине: ζ = λ·l/d. λ: Re ≤ 2000 — 64/Re; Re ≥ 4000 — Альтшуль 0,11(kэ/d + 68/Re)^0,25; между — линейно (чтобы λ была непрерывной). | V21: Дарси–Вейсбах; Альтшуль А.Д., 1982 [С]
A22: 18 | B22: c2 | C22: trans_c2 | D22: diffuser | E22: 0.315 | G22: =$G$21 -> 2998.7509 | J22: 0.4 | K22: 15 | L22: =E22 -> 0.315 | M22: =G22/3600/(PI()*L22^2/4) -> 10.68875 | N22: =M22*L22/'1 Исходные'!$D$7 -> 223569.46 | O22: =IF(N22<=2000,64/N22,IF(N22>=4000,0.11*('1 Исходные'!$D$10/L22+68/N22)^0.25,(1-(N22-2000)/2000)*64/2000+(N22-2000)/2000*0.11*('1 Исходные'!$D$10/L22+68/4000)^0.25)) -> 0.017368939 | P22: =MAX(0,W22-(O22/(8*SIN(RADIANS(K22/2)))*(1-1/(2)^2)))*((1-1/((J22/E22)^2))/0.5)^1.92+(O22/(8*SIN(RADIANS(K22/2)))*(1-1/(((J22/E22)^2))^2)) -> 0.04138164 | Q22: ='1 Исходные'!$D$6*M22^2/2 -> 68.54962 | R22: =P22*Q22 -> 2.8366957 | S22: 2.836696 | T22: =R22-S22 -> -2.9649741e-07 | U22: Переход на больший диаметр (диффузор), к скорости в узком сечении d₁. n = (d₂/d₁)². ζ₂ — таблица при n = 2 (лист 4) по α и Re (интерполяция по α и ln Re); пересчёт на n по формулам Идельчика (5-6), (5-7): ζ = (ζ₂ − ζ_тр(2))·((1 − 1/n)/0,5)^1,92 + ζ_тр(n), ζ_тр = λ/(8 sin(α/2))·(1 − 1/n²) [М]. Колонка W — ζ₂. Параметр 1 = d₂, м; 2 = α, °. | V22: Идельчик, 1992, диагр. 5-2, с. 211; ф. (5-6), (5-7), с. 192–193 [С] — сверено | W22: =(INDEX(OFFSET('4 Таблицы'!$C$33,MIN(MATCH(LN(MIN(MAX(N22,50000),400000)),'4 Таблицы'!$B$33:$B$36,1),3)-1,0,1,15),1,MIN(MATCH(K22,'4 Таблицы'!$C$32:$Q$32,1),14))+(K22-INDEX('4 Таблицы'!$C$32:$Q$32,1,MIN(MATCH(K22,'4 Таблицы'!$C$32:$Q$32,1),14)))*(INDEX(OFFSET('4 Таблицы'!$C$33,MIN(MATCH(LN(MIN(MAX(N22,50000),400000)),'4 Таблицы'!$B$33:$B$36,1),3)-1,0,1,15),1,MIN(MATCH(K22,'4 Таблицы'!$C$32:$Q$32,1),14)+1)-INDEX(OFFSET('4 Таблицы'!$C$33,MIN(MATCH(LN(MIN(MAX(N22,50000),400000)),'4 Таблицы'!$B$33:$B$36,1),3)-1,0,1,15),1,MIN(MATCH(K22,'4 Таблицы'!$C$32:$Q$32,1),14)))/(INDEX('4 Таблицы'!$C$32:$Q$32,1,MIN(MATCH(K22,'4 Таблицы'!$C$32:$Q$32,1),14)+1)-INDEX('4 Таблицы'!$C$32:$Q$32,1,MIN(MATCH(K22,'4 Таблицы'!$C$32:$Q$32,1),14))))+(LN(MIN(MAX(N22,50000),400000))-INDEX('4 Таблицы'!$B$33:$B$36,MIN(MATCH(LN(MIN(MAX(N22,50000),400000)),'4 Таблицы'!$B$33:$B$36,1),3)))/(INDEX('4 Таблицы'!$B$33:$B$36,MIN(MATCH(LN(MIN(MAX(N22,50000),400000)),'4 Таблицы'!$B$33:$B$36,1),3)+1)-INDEX('4 Таблицы'!$B$33:$B$36,MIN(MATCH(LN(MIN(MAX(N22,50000),400000)),'4 Таблицы'!$B$33:$B$36,1),3)))*((INDEX(OFFSET('4 Таблицы'!$C$33,MIN(MATCH(LN(MIN(MAX(N22,50000),400000)),'4 Таблицы'!$B$33:$B$36,1),3),0,1,15),1,MIN(MATCH(K22,'4 Таблицы'!$C$32:$Q$32,1),14))+(K22-INDEX('4 Таблицы'!$C$32:$Q$32,1,MIN(MATCH(K22,'4 Таблицы'!$C$32:$Q$32,1),14)))*(INDEX(OFFSET('4 Таблицы'!$C$33,MIN(MATCH(LN(MIN(MAX(N22,50000),400000)),'4 Таблицы'!$B$33:$B$36,1),3),0,1,15),1,MIN(MATCH(K22,'4 Таблицы'!$C$32:$Q$32,1),14)+1)-INDEX(OFFSET('4 Таблицы'!$C$33,MIN(MATCH(LN(MIN(MAX(N22,50000),400000)),'4 Таблицы'!$B$33:$B$36,1),3),0,1,15),1,MIN(MATCH(K22,'4 Таблицы'!$C$32:$Q$32,1),14)))/(INDEX('4 Таблицы'!$C$32:$Q$32,1,MIN(MATCH(K22,'4 Таблицы'!$C$32:$Q$32,1),14)+1)-INDEX('4 Таблицы'!$C$32:$Q$32,1,MIN(MATCH(K22,'4 Таблицы'!$C$32:$Q$32,1),14))))-(INDEX(OFFSET('4 Таблицы'!$C$33,MIN(MATCH(LN(MIN(MAX(N22,50000),400000)),'4 Таблицы'!$B$33:$B$36,1),3)-1,0,1,15),1,MIN(MATCH(K22,'4 Таблицы'!$C$32:$Q$32,1),14))+(K22-INDEX('4 Таблицы'!$C$32:$Q$32,1,MIN(MATCH(K22,'4 Таблицы'!$C$32:$Q$32,1),14)))*(INDEX(OFFSET('4 Таблицы'!$C$33,MIN(MATCH(LN(MIN(MAX(N22,50000),400000)),'4 Таблицы'!$B$33:$B$36,1),3)-1,0,1,15),1,MIN(MATCH(K22,'4 Таблицы'!$C$32:$Q$32,1),14)+1)-INDEX(OFFSET('4 Таблицы'!$C$33,MIN(MATCH(LN(MIN(MAX(N22,50000),400000)),'4 Таблицы'!$B$33:$B$36,1),3)-1,0,1,15),1,MIN(MATCH(K22,'4 Таблицы'!$C$32:$Q$32,1),14)))/(INDEX('4 Таблицы'!$C$32:$Q$32,1,MIN(MATCH(K22,'4 Таблицы'!$C$32:$Q$32,1),14)+1)-INDEX('4 Таблицы'!$C$32:$Q$32,1,MIN(MATCH(K22,'4 Таблицы'!$C$32:$Q$32,1),14))))) -> 0.065267707
A23: 19 | B23: c2 | C23: teeP3 | D23: teeStraight | E23: 0.4 | G23: =$G$21 -> 2998.7509 | H23: =G23+I23 -> 4498.3003 | I23: =$G$24 -> 1499.5494 | L23: =E23 -> 0.4 | M23: =H23/3600/(PI()*L23^2/4) -> 9.9434268 | N23: =M23*L23/'1 Исходные'!$D$7 -> 264101.64 | P23: =1.55*(I23/H23)-(I23/H23)^2 -> 0.40557833 | Q23: ='1 Исходные'!$D$6*M23^2/2 -> 59.323042 | R23: =P23*Q23 -> 24.06014 | S23: 24.060141 | T23: =R23-S23 -> -9.7841788e-07 | U23: Тройник на слияние, проход. r = Q_б/Q_с (Q_б — боковой поток, колонка I). ζ = 1,55·r − r², к скорости в общем канале (d = d_с). | V23: Идельчик, 1992, диагр. 7-4, с. 346 [С] — сверено
A24: 20 | B24: post3 | C24: hood3 | D24: local | E24: 0.2 | G24: 1499.5494 | J24: 0.2 | L24: =E24 -> 0.2 | M24: =G24/3600/(PI()*L24^2/4) -> 13.258928 | N24: =M24*L24/'1 Исходные'!$D$7 -> 176081.38 | P24: =J24 -> 0.2 | Q24: ='1 Исходные'!$D$6*M24^2/2 -> 105.4795 | R24: =P24*Q24 -> 21.0959 | S24: 21.0959 | T24: =R24-S24 -> -2.0449057e-07 | U24: Вход через конический коллектор (раструб) α = 60°: ζ = 0,25 при l/D = 0,15 и 0,17 при l/D = 0,25 — принято 0,2 (параметр 1). Без раструба (острая кромка) — 0,5. | V24: Идельчик, 1992, диагр. 3-6, с. 127 [С] — сверено; геометрия [Д]
A25: 21 | B25: post3 | C25: branch3 | D25: duct | E25: 0.2 | F25: 6 | G25: =$G$24 -> 1499.5494 | L25: =E25 -> 0.2 | M25: =G25/3600/(PI()*L25^2/4) -> 13.258928 | N25: =M25*L25/'1 Исходные'!$D$7 -> 176081.38 | O25: =IF(N25<=2000,64/N25,IF(N25>=4000,0.11*('1 Исходные'!$D$10/E25+68/N25)^0.25,(1-(N25-2000)/2000)*64/2000+(N25-2000)/2000*0.11*('1 Исходные'!$D$10/E25+68/4000)^0.25)) -> 0.01897902 | P25: =O25*F25/E25 -> 0.56937061 | Q25: ='1 Исходные'!$D$6*M25^2/2 -> 105.4795 | R25: =P25*Q25 -> 60.056927 | S25: 60.056928 | T25: =R25-S25 -> -1.0648319e-06 | U25: Трение по длине: ζ = λ·l/d. λ: Re ≤ 2000 — 64/Re; Re ≥ 4000 — Альтшуль 0,11(kэ/d + 68/Re)^0,25; между — линейно (чтобы λ была непрерывной). | V25: Дарси–Вейсбах; Альтшуль А.Д., 1982 [С]
A26: 22 | B26: post3 | C26: bend90_3 | D26: bend | E26: 0.2 | G26: =$G$24 -> 1499.5494 | J26: 90 | K26: 1.5 | L26: =E26 -> 0.2 | M26: =G26/3600/(PI()*L26^2/4) -> 13.258928 | N26: =M26*L26/'1 Исходные'!$D$7 -> 176081.38 | O26: =IF(N26<=2000,64/N26,IF(N26>=4000,0.11*('1 Исходные'!$D$10/L26+68/N26)^0.25,(1-(N26-2000)/2000)*64/2000+(N26-2000)/2000*0.11*('1 Исходные'!$D$10/L26+68/4000)^0.25)) -> 0.01897902 | P26: =X26*W26*IF(J26>=180,1.4,INDEX('4 Таблицы'!$B$18:$B$28,MATCH(J26,'4 Таблицы'!$A$18:$A$28,1))+(J26-INDEX('4 Таблицы'!$A$18:$A$28,MATCH(J26,'4 Таблицы'!$A$18:$A$28,1)))*(INDEX('4 Таблицы'!$B$18:$B$28,MATCH(J26,'4 Таблицы'!$A$18:$A$28,1)+1)-INDEX('4 Таблицы'!$B$18:$B$28,MATCH(J26,'4 Таблицы'!$A$18:$A$28,1)))/(INDEX('4 Таблицы'!$A$18:$A$28,MATCH(J26,'4 Таблицы'!$A$18:$A$28,1)+1)-INDEX('4 Таблицы'!$A$18:$A$28,MATCH(J26,'4 Таблицы'!$A$18:$A$28,1))))*IF(K26<=1,0.21/K26^2.5,0.21/K26^0.5) -> 0.23943517 | Q26: ='1 Исходные'!$D$6*M26^2/2 -> 105.4795 | R26: =P26*Q26 -> 25.255502 | S26: 25.255502 | T26: =R26-S26 -> -2.8723661e-07 | U26: отвод 90°, R/D = 1,5. Стальной (шероховатый) воздуховод, п. 2 диагр. 6-1: ζ = k_Δ·k_Re·A₁·B₁. A₁ — по таблице (лист 4), B₁ = 0,21/(R/D)^2,5 при R/D ≤ 1, 0,21/(R/D)^0,5 при R/D > 1. k_Re = 1,3 − 0,29·ln(Re·10⁻⁵) при R/D > 0,7. k_Δ: Re 4·10⁴…2·10⁵ — λ_Δ/λ_гл (λ_гл = 1/(1,8 lg Re − 1,64)²), > 2·10⁵ — 1 + Δ̄·10³, сглажено по ln Re на границах [М]. Колонки W, X — k_Re, k_Δ. Параметр 1 = δ, °; 2 = R/D. | V26: Идельчик, 1992, диагр. 6-1, с. 277–278 [С] — сверено | W26: =IF(K26>0.7,1.3-0.29*LN(MAX(N26,10000)*0.00001),IF(K26>0.55,5.45/MAX(N26,10000)^0.131,1+4400/MAX(N26,10000))) -> 1.1359249 | X26: =IF(N26<=32000,1,IF(N26<50000,(1+MIN(1,MAX(0,LN(N26/32000)/LN(50000/32000)))*((O26*(1.8*LOG10(MAX(N26,4000))-1.64)^2)-1)),IF(N26<=160000,(O26*(1.8*LOG10(MAX(N26,4000))-1.64)^2),IF(N26<250000,((O26*(1.8*LOG10(MAX(N26,4000))-1.64)^2)+MIN(1,MAX(0,LN(N26/160000)/LN(250000/160000)))*((1+MIN('1 Исходные'!$D$10/L26,0.001)*1000)-(O26*(1.8*LOG10(MAX(N26,4000))-1.64)^2))),(1+MIN('1 Исходные'!$D$10/L26,0.001)*1000))))) -> 1.2293191
A27: 23 | B27: post3 | C27: bend45_3 | D27: bend | E27: 0.2 | G27: =$G$24 -> 1499.5494 | J27: 45 | K27: 1.5 | L27: =E27 -> 0.2 | M27: =G27/3600/(PI()*L27^2/4) -> 13.258928 | N27: =M27*L27/'1 Исходные'!$D$7 -> 176081.38 | O27: =IF(N27<=2000,64/N27,IF(N27>=4000,0.11*('1 Исходные'!$D$10/L27+68/N27)^0.25,(1-(N27-2000)/2000)*64/2000+(N27-2000)/2000*0.11*('1 Исходные'!$D$10/L27+68/4000)^0.25)) -> 0.01897902 | P27: =X27*W27*IF(J27>=180,1.4,INDEX('4 Таблицы'!$B$18:$B$28,MATCH(J27,'4 Таблицы'!$A$18:$A$28,1))+(J27-INDEX('4 Таблицы'!$A$18:$A$28,MATCH(J27,'4 Таблицы'!$A$18:$A$28,1)))*(INDEX('4 Таблицы'!$B$18:$B$28,MATCH(J27,'4 Таблицы'!$A$18:$A$28,1)+1)-INDEX('4 Таблицы'!$B$18:$B$28,MATCH(J27,'4 Таблицы'!$A$18:$A$28,1)))/(INDEX('4 Таблицы'!$A$18:$A$28,MATCH(J27,'4 Таблицы'!$A$18:$A$28,1)+1)-INDEX('4 Таблицы'!$A$18:$A$28,MATCH(J27,'4 Таблицы'!$A$18:$A$28,1))))*IF(K27<=1,0.21/K27^2.5,0.21/K27^0.5) -> 0.1436611 | Q27: ='1 Исходные'!$D$6*M27^2/2 -> 105.4795 | R27: =P27*Q27 -> 15.153301 | S27: 15.153301 | T27: =R27-S27 -> 2.7658031e-08 | U27: отвод 45°, R/D = 1,5. Стальной (шероховатый) воздуховод, п. 2 диагр. 6-1: ζ = k_Δ·k_Re·A₁·B₁. A₁ — по таблице (лист 4), B₁ = 0,21/(R/D)^2,5 при R/D ≤ 1, 0,21/(R/D)^0,5 при R/D > 1. k_Re = 1,3 − 0,29·ln(Re·10⁻⁵) при R/D > 0,7. k_Δ: Re 4·10⁴…2·10⁵ — λ_Δ/λ_гл (λ_гл = 1/(1,8 lg Re − 1,64)²), > 2·10⁵ — 1 + Δ̄·10³, сглажено по ln Re на границах [М]. Колонки W, X — k_Re, k_Δ. Параметр 1 = δ, °; 2 = R/D. | V27: Идельчик, 1992, диагр. 6-1, с. 277–278 [С] — сверено | W27: =IF(K27>0.7,1.3-0.29*LN(MAX(N27,10000)*0.00001),IF(K27>0.55,5.45/MAX(N27,10000)^0.131,1+4400/MAX(N27,10000))) -> 1.1359249 | X27: =IF(N27<=32000,1,IF(N27<50000,(1+MIN(1,MAX(0,LN(N27/32000)/LN(50000/32000)))*((O27*(1.8*LOG10(MAX(N27,4000))-1.64)^2)-1)),IF(N27<=160000,(O27*(1.8*LOG10(MAX(N27,4000))-1.64)^2),IF(N27<250000,((O27*(1.8*LOG10(MAX(N27,4000))-1.64)^2)+MIN(1,MAX(0,LN(N27/160000)/LN(250000/160000)))*((1+MIN('1 Исходные'!$D$10/L27,0.001)*1000)-(O27*(1.8*LOG10(MAX(N27,4000))-1.64)^2))),(1+MIN('1 Исходные'!$D$10/L27,0.001)*1000))))) -> 1.2293191
A28: 24 | B28: post3 | C28: damper3 | D28: damper | E28: 0.2 | G28: =$G$24 -> 1499.5494 | J28: 7.990537 | L28: =E28 -> 0.2 | M28: =G28/3600/(PI()*L28^2/4) -> 13.258928 | N28: =M28*L28/'1 Исходные'!$D$7 -> 176081.38 | P28: =IF(J28>=90,10000,EXP(LN(INDEX('4 Таблицы'!$B$5:$B$13,MATCH(J28,'4 Таблицы'!$A$5:$A$13,1)))+(J28-INDEX('4 Таблицы'!$A$5:$A$13,MATCH(J28,'4 Таблицы'!$A$5:$A$13,1)))/(INDEX('4 Таблицы'!$A$5:$A$13,MATCH(J28,'4 Таблицы'!$A$5:$A$13,1)+1)-INDEX('4 Таблицы'!$A$5:$A$13,MATCH(J28,'4 Таблицы'!$A$5:$A$13,1)))*(LN(INDEX('4 Таблицы'!$B$5:$B$13,MATCH(J28,'4 Таблицы'!$A$5:$A$13,1)+1))-LN(INDEX('4 Таблицы'!$B$5:$B$13,MATCH(J28,'4 Таблицы'!$A$5:$A$13,1)))))) -> 0.42915679 | Q28: ='1 Исходные'!$D$6*M28^2/2 -> 105.4795 | R28: =P28*Q28 -> 45.267243 | S28: 45.267243 | T28: =R28-S28 -> -1.6664789e-07 | U28: Дроссель-клапан: ζ(α) по таблице листа «4 Таблицы» с интерполяцией по ln ζ. Параметр 1 = угол α, °. | V28: Идельчик, 1992, диагр. 9-17, кривая 2 [С] — сверено
