Workbook

Sheet Как читать
B1: Книга «Модель расчёт v2» — стационарная часть математической модели местной вытяжной вентиляции сварочного участка
B2: Версия 11.10.2026. Каждая цифра здесь считается формулой Excel — можно поменять синюю ячейку и увидеть, как меняется всё остальное.
B4: ЦВЕТА
B5: Синий шрифт на жёлтом — исходные данные (их можно менять). У каждого — источник в последней колонке.
B6: Чёрный шрифт — формула. Зелёный — формула-ссылка на ячейку другого листа.
B7: Оранжевая заливка — число, которое посчитало расчётное ядро (программа на TypeScript, папка vent-sim). Нужно только для сверки на листе «8 Сверка».
B9: СТАТУСЫ ИСТОЧНИКОВ
B10: [Н] — норматив РФ (ГОСТ, СП, СанПиН, методика из перечня Минприроды). [С] — российский справочник или учебник.
B11: [Д] — допущение демонстрационного примера (заменяется паспортом оборудования реального объекта). [А] — параметр, выбранный автором (проверена чувствительность).
B12: [П] — источник найден, но страницу/таблицу надо сверить по бумажной книге. [М] — инженерная модель (приём расчёта, не норматив).
B14: ПОРЯДОК ЛИСТОВ = ПОРЯДОК РАСЧЁТА
B15: 1 Исходные — все входные величины в одном месте.
... B34: 3. Энергия вентилятора общеобменной: при регулировании по выделениям расход бывает больше расчётного; вентилятор теперь подбирается на максимальный расход (иначе мощность считалась при нереальном давлении).

Sheet 1 Исходные
A1: Исходные данные
A2: Все величины, от которых зависит расчёт. Меняйте только синие ячейки. Источник каждой — в колонке H.
A4: № | B4: Величина | C4: Обозн. | D4: Значение | E4: Ед. | F4: Формула (как в книге) | G4: Простыми словами — что это и зачем | H4: Источник / статус
A5: Воздух
A6: 1 | B6: Плотность воздуха | C6: ρ | D6: 1.2 | E6: кг/м³ | F6: — | G6: Сколько весит кубометр воздуха. 1,2 — стандартные условия, при которых испытывают вентиляторы. | H6: ГОСТ 10921-2017, разд. 14 [Н]
A7: 2 | B7: Кинематическая вязкость воздуха (20 °C) | C7: ν | D7: 1.506e-05 | E7: м²/с | F7: — | G7: Насколько воздух «вязкий». Нужна для числа Рейнольдса (режим течения). | H7: Варгафтик Н.Б., 1972 [С][П]
A8: 3 | B8: Теплоёмкость воздуха | C8: c | D8: 1.005 | E8: кДж/(кг·°C) | F8: — | G8: Сколько тепла надо, чтобы нагреть 1 кг воздуха на 1 °C. | H8: Варгафтик Н.Б., 1972 [С][П]
A9: Воздуховоды
A10: 4 | B10: Эквивалентная шероховатость стали | C10: kэ | D10: 0.0001 | E10: м | F10: — | G10: Насколько шершавая стенка воздуховода — влияет на трение. | H10: Справочник проектировщика, ч. 3, кн. 2, 1992; Альтшуль, 1982 [С][П]
A11: 5 | B11: Минимальная транспортная скорость | C11: w_мин | D11: 8 | E11: м/с | F11: — | G11: Ниже этой скорости сварочная пыль начинает оседать в воздуховоде. | H11: Боломатов В.Н., АВОК, 2021, № 3, табл. 4 (8–14 м/с) [С]
A12: Сварка
A13: 6 | B13: Число постов | C13: n | D13: 3 | E13: шт | F13: — | G13: Сколько сварщиков работает одновременно (расчётный случай — все сразу). | H13: Демо-пример (диплом) [Д]
A14: 7 | B14: Сварочный ток | C14: I | D14: 225 | E14: А | F14: — | G14: Ток полуавтомата. Чем больше ток, тем больше плавится проволоки и больше дыма. | H14: Режим для Ø1,2 мм [Д]
A15: 8 | B15: Диаметр проволоки | C15: d | D15: 1.2 | E15: мм | F15: — | H15: Св-08Г2С Ø1,2 [Д]
A16: 9 | B16: Вылет электрода | C16: l | D16: 15 | E16: мм | F16: — | G16: Длина проволоки от токоподвода до дуги (10–20 мм). | H16: Соколов и др., ВолгГТУ, 2016 [С]
A17: 10 | B17: Расход местного отсоса на пост | C17: Q_тр | D17: 1500 | E17: м³/ч | F17: — | G17: Минимум по ГОСТ для сварочного стола. | H17: ГОСТ 12.3.003-86, п. 2.11.1 [Н]
A18: 11 | B18: Эффективность местного отсоса | C18: η | D18: 0.8 | E18: — | F18: — | G18: Какую долю дыма ловит отсос. Остальное (20 %) уходит в цех. | H18: Методика 1997 (приказ Госкомэкологии № 158), разд. 2.1, прим. 1 [Н]
A19: Удельные выделения, г на 1 кг проволоки Св-08Г2С (сварка в CO₂)
A20: 12 | B20: Сварочный аэрозоль (всего) | C20: g_аэр | D20: 10 | E20: г/кг | F20: — | G20: Сколько всего дыма (твёрдых частиц) на килограмм проволоки. | H20: Методика 1997, табл. 1 [Н]
A21: 13 | B21: в т.ч. железа оксид | C21: g_Fe | D21: 7.67 | E21: г/кг | F21: — | H21: там же [Н]
A22: 14 | B22: в т.ч. марганец и его соединения | C22: g_Mn | D22: 1.9 | E22: г/кг | F22: — | G22: Самое вредное в сварочном дыме — по нему считается вентиляция. | H22: там же [Н]; [П: в перечне методик Mn «в пересчёте на MnO₂» — сверить шапку табл. 1]
A23: 15 | B23: в т.ч. пыль с SiO₂ | C23: g_SiO₂ | D23: 0.43 | E23: г/кг | F23: — | H23: там же [Н]
A24: ПДК (рабочая зона) и фон в приточном воздухе
A25: 16 | B25: ПДК марганца (сварочный аэрозоль, Mn ≤ 20 %), среднесменная | C25: ПДК_Mn | D25: 0.2 | E25: мг/м³ | F25: — | G25: Предельная концентрация в воздухе рабочей зоны. Берём среднесменную (строже максимально разовой 0,6) — в запас. | H25: СанПиН 1.2.3685-21, табл. 2.1 [Н] (сверено)
A26: 17 | B26: Марганец в приточном (наружном) воздухе | C26: q_пр,Mn | D26: 0.001 | E26: мг/м³ | F26: — | G26: Сколько марганца уже есть в наружном воздухе. Берём ПДК атмосферы — верхняя оценка. | H26: СанПиН 1.2.3685-21, табл. 1.1, поз. 302 [Н]; СП 60, п. 5.11
A27: 18 | B27: ПДК железа оксида | C27: ПДК_Fe | D27: 6 | E27: мг/м³ | F27: — | H27: СанПиН 1.2.3685-21, табл. 2.1 [П: сверить строку]
A28: 19 | B28: Железа оксид в приточном воздухе | C28: q_пр,Fe | D28: 0.04 | E28: мг/м³ | F28: — | H28: СанПиН, табл. 1.1 (ПДК с.с. атм.) [П]
A29: 20 | B29: ПДК пыли с SiO₂ 20–70 % (с.с.) | C29: ПДК_SiO₂ | D29: 1 | E29: мг/м³ | F29: — | H29: СанПиН, табл. 2.1 [П]
A30: Климат (холодный период) и помещение
A31: 21 | B31: Температура в цехе | C31: t_в | D31: 18 | E31: °C | F31: — | G31: Середина оптимума 17–19 °C для работ категории IIб. | H31: СанПиН 1.2.3685-21, разд. V [Н][П: № таблицы]
A32: 22 | B32: Средняя температура отопительного периода (Москва) | C32: t_оп | D32: -1.7 | E32: °C | F32: — | G32: Средняя температура наружного воздуха за отопительный период. | H32: СП 131.13330.2025, табл. 3.1 [Н]
A33: 23 | B33: Продолжительность отопительного периода | C33: z_оп | D33: 202 | E33: сут | F33: — | H33: СП 131.13330.2025, табл. 3.1 [Н]
A34: 24 | B34: Длительность смены | C34: t_см | D34: 8 | E34: ч | F34: — | H34: [Д]
A35: 25 | B35: Объём цеха | C35: V | D35: 16588.8 | E35: м³ | F35: 48 × 24 × 14,4 м | G35: Нужен для динамики (как быстро растёт концентрация), на стационарный расчёт не влияет. | H35: Диплом [Д]

Sheet 2 Выделения
A1: Выделение вредных веществ при сварке
A2: Шаг 1: по току считаем, сколько проволоки плавится в час. Шаг 2: умножаем на удельные выделения из Методики. Шаг 3: делим — η ловит отсос, (1 − η) уходит в цех.
A4: № | B4: Величина | C4: Обозн. | D4: Значение | E4: Ед. | F4: Формула (как в книге) | G4: Простыми словами — что это и зачем | H4: Источник / статус
A5: Расход проволоки
A6: 1 | B6: Коэффициент расплавления | C6: α_р | D6: =9.05+0.00031*'1 Исходные'!$D$14*'1 Исходные'!$D$16/'1 Исходные'!$D$15^2 -> 9.7765625 | E6: г/(А·ч) | F6: α_р = 9,05 + 3,1·10⁻⁴·I·l/d² | G6: Сколько граммов проволоки плавит каждый ампер за час. Растёт с током и вылетом (проволока подогревается током). | H6: Соколов Г.Н. и др. Технология и материалы для сварки и наплавки. ВолгГТУ, 2016, ф. (3.22) [С][П]
A7: 2 | B7: Расход проволоки | C7: B | D7: ='2 Выделения'!$D$6*'1 Исходные'!$D$14/1000 -> 2.1997266 | E7: кг/ч | F7: B = α_р·I / 1000 | G7: Килограммы проволоки в час на одном посту. | H7: там же
A8: Выделение на одном посту (дуга горит)
A9: 3 | B9: Аэрозоль | C9: G_аэр | D9: ='1 Исходные'!$D$20*'2 Выделения'!$D$7 -> 21.997266 | E9: г/ч | F9: G = g·B | G9: Граммов дыма в час. | H9: Методика 1997, разд. 2.1, ф. (2.1) [Н]
A10: 4 | B10: Марганец | C10: G_Mn | D10: ='1 Исходные'!$D$22*'2 Выделения'!$D$7 -> 4.1794805 | E10: г/ч | F10: G = g·B | H10: там же
A11: 5 | B11: Железа оксид | C11: G_Fe | D11: ='1 Исходные'!$D$21*'2 Выделения'!$D$7 -> 16.871903 | E11: г/ч | F11: G = g·B | H11: там же
A12: 6 | B12: Пыль с SiO₂ | C12: G_SiO₂ | D12: ='1 Исходные'!$D$23*'2 Выделения'!$D$7 -> 0.94588242 | E12: г/ч | F12: G = g·B | H12: там же
A13: 7 | B13: Проверка: сумма компонентов = аэрозоль | D13: ='1 Исходные'!$D$21+'1 Исходные'!$D$22+'1 Исходные'!$D$23-'1 Исходные'!$D$20 -> 0 | E13: г/кг | F13: Σg_i − g_аэр | G13: Должно быть 0: в Методике аэрозоль = сумма твёрдых компонентов. Это проверка, что числа переписаны без ошибки. | H13: проверка
A14: Куда уходит марганец (все посты)
A15: 8 | B15: Выделяется на всех постах | C15: ΣG_Mn | D15: ='2 Выделения'!$D$10*'1 Исходные'!$D$13*1000 -> 12538.441 | E15: мг/ч | F15: n·G_Mn
A16: 9 | B16: Ловят местные отсосы | C16: η·ΣG | D16: ='1 Исходные'!$D$18*'2 Выделения'!$D$15 -> 10030.753 | E16: мг/ч | F16: η·ΣG | G16: Уходит через отсос → фильтр → выброс. | H16: Методика 1997, разд. 2.1 [Н]
A17: 10 | B17: Поступает в воздух цеха | C17: m_по | D17: =(1-'1 Исходные'!$D$18)*'2 Выделения'!$D$15 -> 2507.6883 | E17: мг/ч | F17: (1 − η)·ΣG | G17: Вот это и должна разбавить вентиляция — это m_по в формуле СП 60. | H17: СП 60.13330.2020 (обозначение m_po) [Н]
A18: 11 | B18: Железа оксид в воздух цеха | C18: m_Fe | D18: =(1-'1 Исходные'!$D$18)*'2 Выделения'!$D$11*'1 Исходные'!$D$13*1000 -> 10123.142 | E18: мг/ч | F18: (1 − η)·n·G_Fe
A19: 12 | B19: SiO₂ в воздух цеха | C19: m_SiO₂ | D19: =(1-'1 Исходные'!$D$18)*'2 Выделения'!$D$12*'1 Исходные'!$D$13*1000 -> 567.52945 | E19: мг/ч | F19: (1 − η)·n·G_SiO₂
B20: Оседание аэрозоля (коэффициент 0,4 по Методике, разд. 2.3) в базовом расчёте НЕ учитывается — это запас. Вариант с оседанием посчитан в ядре (лист 9).

Sheet 3 СП 60
A1: Воздухообмен по СП 60.13330.2020 (ассимиляция вредных веществ)
A2: Формула СП 60 (та же — СНиП 2.04.05-91*, прил. 17): L = L_wz + (m_по − L_wz·(q_wz − q_пр)) / (q_l − q_пр). L — сколько всего воздуха надо удалить из цеха (= подать притоком). Сюда входят и местные отсосы L_wz, поэтому общеобменная = L − L_wz.
A4: № | B4: Величина | C4: Обозн. | D4: Значение | E4: Ед. | F4: Формула (как в книге) | G4: Простыми словами — что это и зачем | H4: Источник / статус
A5: Марганец (лимитирующее вещество)
A6: 1 | B6: Воздух, удаляемый местными отсосами | C6: L_wz | D6: ='1 Исходные'!$D$17*'1 Исходные'!$D$13 -> 4500 | E6: м³/ч | F6: L_wz = n·Q_тр | G6: Отсосы уносят воздух из цеха вместе с остатком дыма — этот воздух тоже участвует в разбавлении. | H6: СП 60.13330.2020 [Н]
A7: 2 | B7: Допустимая концентрация в рабочей зоне | C7: q_wz | D7: ='1 Исходные'!$D$25 -> 0.2 | E7: мг/м³ | F7: q_wz = ПДК | H7: СП 60, ГОСТ 12.1.005-88 [Н]
A8: 3 | B8: Концентрация в приточном воздухе | C8: q_пр | D8: ='1 Исходные'!$D$26 -> 0.001 | E8: мг/м³
A9: 4 | B9: Концентрация в воздухе, удаляемом из верхней зоны | C9: q_l | D9: ='3 СП 60'!$D$7 -> 0.2 | E9: мг/м³ | F9: q_l = q_wz (допущение) | G9: Принято, что воздух перемешан полностью. На деле сварочный дым поднимается и наверху концентрация больше — значит реальный расход меньше, допущение идёт в запас. | H9: [Д] — в запас
A10: 5 | B10: Весь воздухообмен (приток = вся вытяжка) | C10: L | D10: ='3 СП 60'!$D$6+('2 Выделения'!$D$17-'3 СП 60'!$D$6*('3 СП 60'!$D$7-'3 СП 60'!$D$8))/('3 СП 60'!$D$9-'3 СП 60'!$D$8) -> 12601.449 | E10: м³/ч | F10: L = L_wz + (m_по − L_wz·(q_wz − q_пр))/(q_l − q_пр) | G10: Сколько воздуха надо удалить всего, чтобы марганца было не больше ПДК. | H10: СП 60.13330.2020 [Н]
A11: 6 | B11: Общеобменная вытяжка (сверх местных отсосов) | C11: L_оо | D11: =MAX(0,'3 СП 60'!$D$10-'3 СП 60'!$D$6) -> 8101.4486 | E11: м³/ч | F11: L_оо = L − L_wz | G11: Столько должен удалять вентилятор общеобменной вентиляции.
A12: 7 | B12: Проверка: при q_l = q_wz формула упрощается | C12: L | D12: ='2 Выделения'!$D$17/('3 СП 60'!$D$7-'3 СП 60'!$D$8) -> 12601.449 | E12: м³/ч | F12: L = m_по/(q_wz − q_пр) | G12: Должно совпасть с L выше — значит формула введена верно. | H12: алгебра
A13: 8 | B13: Проверка: концентрация при найденном L | C13: C | D13: ='3 СП 60'!$D$8+'2 Выделения'!$D$17/'3 СП 60'!$D$10 -> 0.2 | E13: мг/м³ | F13: C = q_пр + m_по/L | G13: Должно получиться ровно ПДК (0,2). | H13: баланс массы
A14: 9 | B14: Как было в дипломе и в модели до 11.10.2026 (ОШИБКА) | C14: L_оо,стар | D14: ='2 Выделения'!$D$17/('3 СП 60'!$D$7-'3 СП 60'!$D$8) -> 12601.449 | E14: м³/ч | F14: L_оо = m_по/(ПДК − q_пр) | G14: Весь потребный воздух отдавали общеобменной и ещё добавляли местные отсосы сверху — воздух отсосов считался дважды. | H14: ошибка — в запас
A15: 10 | B15: Перерасход из-за ошибки | C15: ΔL | D15: ='3 СП 60'!$D$14-'3 СП 60'!$D$11 -> 4500 | E15: м³/ч | F15: L_оо,стар − L_оо | G15: Ровно расход местных отсосов.
A16: Другие вещества — проверка, что лимитирует марганец
A17: 11 | B17: Весь воздухообмен по железа оксиду | C17: L_Fe | D17: ='2 Выделения'!$D$18/('1 Исходные'!$D$27-'1 Исходные'!$D$28) -> 1698.5137 | E17: м³/ч | F17: L = m/(ПДК − q_пр) | G17: Меньше, чем по марганцу — значит определяет марганец. | H17: СП 60 [Н]
A18: 12 | B18: Весь воздухообмен по SiO₂ | C18: L_SiO₂ | D18: ='2 Выделения'!$D$19/'1 Исходные'!$D$29 -> 567.52945 | E18: м³/ч | F18: L = m/ПДК | H18: СП 60 [Н]
A19: 13 | B19: Расчётный (наибольший) | C19: L_расч | D19: =MAX('3 СП 60'!$D$10,'3 СП 60'!$D$17,'3 СП 60'!$D$18) -> 12601.449 | E19: м³/ч | F19: max по веществам | G19: Если вещества однонаправленного действия — по СП 60 расходы СКЛАДЫВАЮТСЯ (Σ m_i/(ПДК_i − q_пр,i)). Mn, Fe₂O₃ и SiO₂ к одной группе не относятся. | H19: СП 60.13330.2020 [Н]
A20: Что ещё требует СП 60 и как это учтено
B21: 1) Расходы определяются отдельно для тёплого и холодного периодов — в модели считается холодный (по нему максимальные затраты тепла). 2) Теплопоступления от дуги на расход по вредным веществам не влияют (одинаковы во всех режимах) — не моделируются. 3) Рециркуляция не применяется: Mn — 2-й класс опасности. 4) Минимум наружного воздуха на человека (СП 60, прил. [П: номер]) — десятки м³/ч; у нас ≥ 1500 м³/ч на сварщика — выполняется с большим запасом. 5) Местные отсосы и общеобменная вытяжка компенсируются притоком того же расхода — поэтому тепло считается от L (лист 7).

Sheet 4 Заслонка
A1: Характеристика дроссель-клапана (круглый воздуховод): угол → ζ
A2: 0° — открыта, 90° — закрыта. Между точками таблицы ζ интерполируется по логарифму (ζ растёт почти экспоненциально): ln ζ = ln ζ₀ + (α − α₀)/(α₁ − α₀)·(ln ζ₁ − ln ζ₀). Источник: Идельчик И.Е., 1992 (дроссель-клапан в круглой трубе) [П: сверить значения]; 70–90° — [Д] утечка закрытой заслонки.
A4: α, ° | B4: ζ | C4: ln ζ | D4: Комментарий
A5: 0 | B5: 0.2 | C5: =LN(B5) -> -1.6094379 | D5: [П] Идельчик
A6: 5 | B6: 0.24 | C6: =LN(B6) -> -1.4271164 | D6: [П] Идельчик
A7: 10 | B7: 0.52 | C7: =LN(B7) -> -0.65392647 | D7: [П] Идельчик
A8: 15 | B8: 0.9 | C8: =LN(B8) -> -0.10536052 | D8: [П] Идельчик
A9: 20 | B9: 1.54 | C9: =LN(B9) -> 0.43178242 | D9: [П] Идельчик
A10: 25 | B10: 2.51 | C10: =LN(B10) -> 0.92028275 | D10: [П] Идельчик
A11: 30 | B11: 3.91 | C11: =LN(B11) -> 1.3635374 | D11: [П] Идельчик
A12: 35 | B12: 6.22 | C12: =LN(B12) -> 1.8277699 | D12: [П] Идельчик
A13: 40 | B13: 10.8 | C13: =LN(B13) -> 2.3795461 | D13: [П] Идельчик
A14: 45 | B14: 18.7 | C14: =LN(B14) -> 2.9285235 | D14: [П] Идельчик
A15: 50 | B15: 32.6 | C15: =LN(B15) -> 3.4843123 | D15: [П] Идельчик
A16: 55 | B16: 58.8 | C16: =LN(B16) -> 4.0741419 | D16: [П] Идельчик
... A20: 90 | B20: 10000 | C20: =LN(B20) -> 9.2103404 | D20: [Д] закрыто (утечка)

Sheet 5 Потери
A1: Потери давления на каждом элементе сети — режим пусконаладки: 3 поста по 1500 м³/ч
A2: Общая формула: Δp = ζ·p_д, p_д = ρw²/2 (динамическое давление), w = Q/F. Для воздуховода ζ = λ·l/d (трение), λ — по Альтшулю: λ = 0,11·(kэ/d + 68/Re)^0,25. Для тройников ζ отнесён к скорости в ОБЩЕМ (сборном) канале — поэтому для них w и p_д считаются по d_с и Q_с. Расходы постов (синие, колонка G в строках «зонт») — это решение сети из ядра при углах заслонок пусконаладки; Excel их не решает, а ПРОВЕРЯЕТ: сумма потерь по пути каждого поста должна равняться давлению вентилятора (лист 6). Расходы участков коллектора — сумма постов (закон сохранения массы).
A4: № | B4: Участок | C4: Элемент | D4: Тип | E4: d (d₁), м | F4: l, м | G4: Q, м³/ч | H4: Q_с, м³/ч (общий канал) | I4: Q_б, м³/ч (боковой поток) | J4: Параметр 1 | K4: Параметр 2 | L4: d расч., м | M4: w, м/с | N4: Re | O4: λ | P4: ζ | Q4: p_д, Па | R4: Δp, Па (Excel) | S4: Δp, Па (ядро) | T4: Разница, Па | U4: Формула ζ / пояснение | V4: Источник
A5: 1 | B5: post1 | C5: hood1 | D5: local | E5: 0.2 | G5: 1499.1102 | J5: 0.2 | L5: =E5 -> 0.2 | M5: =G5/3600/(PI()*L5^2/4) -> 13.255044 | N5: =M5*L5/'1 Исходные'!$D$7 -> 176029.81 | P5: =J5 -> 0.2 | Q5: ='1 Исходные'!$D$6*M5^2/2 -> 105.41772 | R5: =P5*Q5 -> 21.083544 | S5: 21.083544 | T5: =R5-S5 -> 1.3408226e-07 | U5: Вход через конический зонт (коллектор): ζ = 0,2 (параметр 1). Без зонта (острая кромка) было бы 0,5. | V5: Идельчик, 1992, разд. 3 [С][П: по диаграмме]
A6: 2 | B6: post1 | C6: branch1 | D6: duct | E6: 0.2 | F6: 6 | G6: =$G$5 -> 1499.1102 | L6: =E6 -> 0.2 | M6: =G6/3600/(PI()*L6^2/4) -> 13.255044 | N6: =M6*L6/'1 Исходные'!$D$7 -> 176029.81 | O6: =IF(N6<=2000,64/N6,IF(N6>=4000,0.11*('1 Исходные'!$D$10/E6+68/N6)^0.25,(1-(N6-2000)/2000)*64/2000+(N6-2000)/2000*0.11*('1 Исходные'!$D$10/E6+68/4000)^0.25)) -> 0.018979626 | P6: =O6*F6/E6 -> 0.56938878 | Q6: ='1 Исходные'!$D$6*M6^2/2 -> 105.41772 | R6: =P6*Q6 -> 60.023668 | S6: 60.023667 | T6: =R6-S6 -> 8.8353691e-07 | U6: Трение по длине: ζ = λ·l/d. λ: Re ≤ 2000 — 64/Re; Re ≥ 4000 — Альтшуль 0,11(kэ/d + 68/Re)^0,25; между — линейно (чтобы λ была непрерывной). | V6: Дарси–Вейсбах; Альтшуль А.Д., 1982 [С]
A7: 3 | B7: post1 | C7: bend90_1 | D7: local | E7: 0.2 | G7: =$G$5 -> 1499.1102 | J7: 90 | K7: 1.5 | L7: =E7 -> 0.2 | M7: =G7/3600/(PI()*L7^2/4) -> 13.255044 | N7: =M7*L7/'1 Исходные'!$D$7 -> 176029.81 | P7: =(0.0000001634831*J7^3-0.000081581126*J7^2+0.01714184*J7)*IF(K7<1,0.21/K7^2.5,0.21/K7^0.5) -> 0.17165935 | Q7: ='1 Исходные'!$D$6*M7^2/2 -> 105.41772 | R7: =P7*Q7 -> 18.095937 | S7: 18.095937 | T7: =R7-S7 -> 4.0136949e-07 | U7: отвод 90°, R/D = 1,5. ζ = A₁·B₁; A₁ = 1,634831·10⁻⁷δ³ − 8,1581126·10⁻⁵δ² + 1,714184·10⁻²δ (A₁(90°) = 1,00); B₁ = 0,21/(R/D)^2,5 при R/D < 1, 0,21/(R/D)^0,5 при R/D ≥ 1. Параметр 1 = δ, °; параметр 2 = R/D. | V7: Идельчик И.Е., 1992, разд. 6, диагр. 6-1 [С][П]
A8: 4 | B8: post1 | C8: bend45_1 | D8: local | E8: 0.2 | G8: =$G$5 -> 1499.1102 | J8: 45 | K8: 1.5 | L8: =E8 -> 0.2 | M8: =G8/3600/(PI()*L8^2/4) -> 13.255044 | N8: =M8*L8/'1 Исходные'!$D$7 -> 176029.81 | P8: =(0.0000001634831*J8^3-0.000081581126*J8^2+0.01714184*J8)*IF(K8<1,0.21/K8^2.5,0.21/K8^0.5) -> 0.10649276 | Q8: ='1 Исходные'!$D$6*M8^2/2 -> 105.41772 | R8: =P8*Q8 -> 11.226225 | S8: 11.226224 | T8: =R8-S8 -> 5.4272612e-07 | U8: отвод 45°, R/D = 1,5. ζ = A₁·B₁; A₁ = 1,634831·10⁻⁷δ³ − 8,1581126·10⁻⁵δ² + 1,714184·10⁻²δ (A₁(90°) = 1,00); B₁ = 0,21/(R/D)^2,5 при R/D < 1, 0,21/(R/D)^0,5 при R/D ≥ 1. Параметр 1 = δ, °; параметр 2 = R/D. | V8: Идельчик И.Е., 1992, разд. 6, диагр. 6-1 [С][П]
A9: 5 | B9: post1 | C9: damper1 | D9: damper | E9: 0.2 | G9: =$G$5 -> 1499.1102 | J9: 0 | L9: =E9 -> 0.2 | M9: =G9/3600/(PI()*L9^2/4) -> 13.255044 | N9: =M9*L9/'1 Исходные'!$D$7 -> 176029.81 | P9: =IF(J9>=90,10000,EXP(LN(INDEX('4 Заслонка'!$B$5:$B$20,MATCH(J9,'4 Заслонка'!$A$5:$A$20,1)))+(J9-INDEX('4 Заслонка'!$A$5:$A$20,MATCH(J9,'4 Заслонка'!$A$5:$A$20,1)))/(INDEX('4 Заслонка'!$A$5:$A$20,MATCH(J9,'4 Заслонка'!$A$5:$A$20,1)+1)-INDEX('4 Заслонка'!$A$5:$A$20,MATCH(J9,'4 Заслонка'!$A$5:$A$20,1)))*(LN(INDEX('4 Заслонка'!$B$5:$B$20,MATCH(J9,'4 Заслонка'!$A$5:$A$20,1)+1))-LN(INDEX('4 Заслонка'!$B$5:$B$20,MATCH(J9,'4 Заслонка'!$A$5:$A$20,1)))))) -> 0.2 | Q9: ='1 Исходные'!$D$6*M9^2/2 -> 105.41772 | R9: =P9*Q9 -> 21.083544 | S9: 21.083544 | T9: =R9-S9 -> 1.3408226e-07 | U9: Дроссель-клапан: ζ(α) по таблице листа «4 Заслонка» с интерполяцией по ln ζ. Параметр 1 = угол α, °. | V9: Идельчик, 1992 [С][П]
A10: 6 | B10: post1 | C10: bend_end | D10: local | E10: 0.2 | G10: =$G$5 -> 1499.1102 | J10: 90 | K10: 1 | L10: =E10 -> 0.2 | M10: =G10/3600/(PI()*L10^2/4) -> 13.255044 | N10: =M10*L10/'1 Исходные'!$D$7 -> 176029.81 | P10: =(0.0000001634831*J10^3-0.000081581126*J10^2+0.01714184*J10)*IF(K10<1,0.21/K10^2.5,0.21/K10^0.5) -> 0.21023891 | Q10: ='1 Исходные'!$D$6*M10^2/2 -> 105.41772 | R10: =P10*Q10 -> 22.162907 | S10: 22.162906 | T10: =R10-S10 -> 5.2535053e-07 | U10: отвод 90°, R/D = 1 (в торец коллектора). ζ = A₁·B₁; A₁ = 1,634831·10⁻⁷δ³ − 8,1581126·10⁻⁵δ² + 1,714184·10⁻²δ (A₁(90°) = 1,00); B₁ = 0,21/(R/D)^2,5 при R/D < 1, 0,21/(R/D)^0,5 при R/D ≥ 1. Параметр 1 = δ, °; параметр 2 = R/D. | V10: Идельчик И.Е., 1992, разд. 6, диагр. 6-1 [С][П]
A11: 7 | B11: post1 | C11: trans1 | D11: diffuser | E11: 0.2 | G11: =$G$5 -> 1499.1102 | J11: 0.25 | K11: 15 | L11: =E11 -> 0.2 | M11: =G11/3600/(PI()*L11^2/4) -> 13.255044 | N11: =M11*L11/'1 Исходные'!$D$7 -> 176029.81 | P11: =IF(K11>40,(1-(E11/J11)^2)^2,MIN((1-(E11/J11)^2)^2,3.2*TAN(RADIANS(K11/2))^1.25*(1-(E11/J11)^2)^2)) -> 0.032888295 | Q11: ='1 Исходные'!$D$6*M11^2/2 -> 105.41772 | R11: =P11*Q11 -> 3.4670091 | S11: 3.467009 | T11: =R11-S11 -> 8.5516989e-08 | U11: Переход на больший диаметр (диффузор). n = (1 − F₁/F₂)² — внезапное расширение (Борда–Карно); при угле α ≤ 40°: ζ = 3,2·tg(α/2)^1,25·n, но не больше n. К скорости в узком сечении d₁. Параметр 1 = d₂, м; параметр 2 = α, °. | V11: Идельчик, 1992, разд. 5 [С][П]
A12: 8 | B12: c1 | C12: c1 | D12: duct | E12: 0.25 | F12: 5 | G12: =$G$5 -> 1499.1102 | L12: =E12 -> 0.25 | M12: =G12/3600/(PI()*L12^2/4) -> 8.4832284 | N12: =M12*L12/'1 Исходные'!$D$7 -> 140823.84 | O12: =IF(N12<=2000,64/N12,IF(N12>=4000,0.11*('1 Исходные'!$D$10/E12+68/N12)^0.25,(1-(N12-2000)/2000)*64/2000+(N12-2000)/2000*0.11*('1 Исходные'!$D$10/E12+68/4000)^0.25)) -> 0.018961261 | P12: =O12*F12/E12 -> 0.37922522 | Q12: ='1 Исходные'!$D$6*M12^2/2 -> 43.179098 | R12: =P12*Q12 -> 16.374603 | S12: 16.374603 | T12: =R12-S12 -> 6.7936906e-08 | U12: Трение по длине: ζ = λ·l/d. λ: Re ≤ 2000 — 64/Re; Re ≥ 4000 — Альтшуль 0,11(kэ/d + 68/Re)^0,25; между — линейно (чтобы λ была непрерывной). | V12: Дарси–Вейсбах; Альтшуль А.Д., 1982 [С]
A13: 9 | B13: c1 | C13: trans_c1 | D13: diffuser | E13: 0.25 | G13: =$G$12 -> 1499.1102 | J13: 0.315 | K13: 15 | L13: =E13 -> 0.25 | M13: =G13/3600/(PI()*L13^2/4) -> 8.4832284 | N13: =M13*L13/'1 Исходные'!$D$7 -> 140823.84 | P13: =IF(K13>40,(1-(E13/J13)^2)^2,MIN((1-(E13/J13)^2)^2,3.2*TAN(RADIANS(K13/2))^1.25*(1-(E13/J13)^2)^2)) -> 0.03476304 | Q13: ='1 Исходные'!$D$6*M13^2/2 -> 43.179098 | R13: =P13*Q13 -> 1.5010367 | S13: 1.501037 | T13: =R13-S13 -> -2.682687e-07 | U13: Переход на больший диаметр (диффузор). n = (1 − F₁/F₂)² — внезапное расширение (Борда–Карно); при угле α ≤ 40°: ζ = 3,2·tg(α/2)^1,25·n, но не больше n. К скорости в узком сечении d₁. Параметр 1 = d₂, м; параметр 2 = α, °. | V13: Идельчик, 1992, разд. 5 [С][П]
A14: 10 | B14: c1 | C14: teeP2 | D14: teeStraight | E14: 0.315 | G14: =$G$12 -> 1499.1102 | H14: =G14+I14 -> 2999.1107 | I14: =$G$15 -> 1500.0005 | L14: =E14 -> 0.315 | M14: =H14/3600/(PI()*L14^2/4) -> 10.690032 | N14: =M14*L14/'1 Исходные'!$D$7 -> 223596.29 | P14: =1.55*(I14/H14)-(I14/H14)^2 -> 0.52508161 | Q14: ='1 Исходные'!$D$6*M14^2/2 -> 68.566071 | R14: =P14*Q14 -> 36.002783 | S14: 36.002783 | T14: =R14-S14 -> 1.1152281e-07 | U14: Тройник на слияние, проход. r = Q_б/Q_с (Q_б — боковой поток, колонка I). ζ = 1,55·r − r², к скорости в общем канале (d = d_с). | V14: Идельчик, 1992, разд. 7, диагр. 7-1 [С][П]
A15: 11 | B15: post2 | C15: hood2 | D15: local | E15: 0.2 | G15: 1500.0005 | J15: 0.2 | L15: =E15 -> 0.2 | M15: =G15/3600/(PI()*L15^2/4) -> 13.262916 | N15: =M15*L15/'1 Исходные'!$D$7 -> 176134.35 | P15: =J15 -> 0.2 | Q15: ='1 Исходные'!$D$6*M15^2/2 -> 105.54297 | R15: =P15*Q15 -> 21.108594 | S15: 21.108594 | T15: =R15-S15 -> -2.1240005e-09 | U15: Вход через конический зонт (коллектор): ζ = 0,2 (параметр 1). Без зонта (острая кромка) было бы 0,5. | V15: Идельчик, 1992, разд. 3 [С][П: по диаграмме]
A16: 12 | B16: post2 | C16: branch2 | D16: duct | E16: 0.2 | F16: 6 | G16: =$G$15 -> 1500.0005 | L16: =E16 -> 0.2 | M16: =G16/3600/(PI()*L16^2/4) -> 13.262916 | N16: =M16*L16/'1 Исходные'!$D$7 -> 176134.35 | O16: =IF(N16<=2000,64/N16,IF(N16>=4000,0.11*('1 Исходные'!$D$10/E16+68/N16)^0.25,(1-(N16-2000)/2000)*64/2000+(N16-2000)/2000*0.11*('1 Исходные'!$D$10/E16+68/4000)^0.25)) -> 0.018978399 | P16: =O16*F16/E16 -> 0.56935196 | Q16: ='1 Исходные'!$D$6*M16^2/2 -> 105.54297 | R16: =P16*Q16 -> 60.091096 | S16: 60.091096 | T16: =R16-S16 -> 4.9817418e-07 | U16: Трение по длине: ζ = λ·l/d. λ: Re ≤ 2000 — 64/Re; Re ≥ 4000 — Альтшуль 0,11(kэ/d + 68/Re)^0,25; между — линейно (чтобы λ была непрерывной). | V16: Дарси–Вейсбах; Альтшуль А.Д., 1982 [С]
A17: 13 | B17: post2 | C17: bend90_2 | D17: local | E17: 0.2 | G17: =$G$15 -> 1500.0005 | J17: 90 | K17: 1.5 | L17: =E17 -> 0.2 | M17: =G17/3600/(PI()*L17^2/4) -> 13.262916 | N17: =M17*L17/'1 Исходные'!$D$7 -> 176134.35 | P17: =(0.0000001634831*J17^3-0.000081581126*J17^2+0.01714184*J17)*IF(K17<1,0.21/K17^2.5,0.21/K17^0.5) -> 0.17165935 | Q17: ='1 Исходные'!$D$6*M17^2/2 -> 105.54297 | R17: =P17*Q17 -> 18.117438 | S17: 18.117437 | T17: =R17-S17 -> 6.1804282e-07 | U17: отвод 90°, R/D = 1,5. ζ = A₁·B₁; A₁ = 1,634831·10⁻⁷δ³ − 8,1581126·10⁻⁵δ² + 1,714184·10⁻²δ (A₁(90°) = 1,00); B₁ = 0,21/(R/D)^2,5 при R/D < 1, 0,21/(R/D)^0,5 при R/D ≥ 1. Параметр 1 = δ, °; параметр 2 = R/D. | V17: Идельчик И.Е., 1992, разд. 6, диагр. 6-1 [С][П]
A18: 14 | B18: post2 | C18: bend45_2 | D18: local | E18: 0.2 | G18: =$G$15 -> 1500.0005 | J18: 45 | K18: 1.5 | L18: =E18 -> 0.2 | M18: =G18/3600/(PI()*L18^2/4) -> 13.262916 | N18: =M18*L18/'1 Исходные'!$D$7 -> 176134.35 | P18: =(0.0000001634831*J18^3-0.000081581126*J18^2+0.01714184*J18)*IF(K18<1,0.21/K18^2.5,0.21/K18^0.5) -> 0.10649276 | Q18: ='1 Исходные'!$D$6*M18^2/2 -> 105.54297 | R18: =P18*Q18 -> 11.239563 | S18: 11.239562 | T18: =R18-S18 -> 6.8900384e-07 | U18: отвод 45°, R/D = 1,5. ζ = A₁·B₁; A₁ = 1,634831·10⁻⁷δ³ − 8,1581126·10⁻⁵δ² + 1,714184·10⁻²δ (A₁(90°) = 1,00); B₁ = 0,21/(R/D)^2,5 при R/D < 1, 0,21/(R/D)^0,5 при R/D ≥ 1. Параметр 1 = δ, °; параметр 2 = R/D. | V18: Идельчик И.Е., 1992, разд. 6, диагр. 6-1 [С][П]
A19: 15 | B19: post2 | C19: damper2 | D19: damper | E19: 0.2 | G19: =$G$15 -> 1500.0005 | J19: 3.000361 | L19: =E19 -> 0.2 | M19: =G19/3600/(PI()*L19^2/4) -> 13.262916 | N19: =M19*L19/'1 Исходные'!$D$7 -> 176134.35 | P19: =IF(J19>=90,10000,EXP(LN(INDEX('4 Заслонка'!$B$5:$B$20,MATCH(J19,'4 Заслонка'!$A$5:$A$20,1)))+(J19-INDEX('4 Заслонка'!$A$5:$A$20,MATCH(J19,'4 Заслонка'!$A$5:$A$20,1)))/(INDEX('4 Заслонка'!$A$5:$A$20,MATCH(J19,'4 Заслонка'!$A$5:$A$20,1)+1)-INDEX('4 Заслонка'!$A$5:$A$20,MATCH(J19,'4 Заслонка'!$A$5:$A$20,1)))*(LN(INDEX('4 Заслонка'!$B$5:$B$20,MATCH(J19,'4 Заслонка'!$A$5:$A$20,1)+1))-LN(INDEX('4 Заслонка'!$B$5:$B$20,MATCH(J19,'4 Заслонка'!$A$5:$A$20,1)))))) -> 0.22312306 | Q19: ='1 Исходные'!$D$6*M19^2/2 -> 105.54297 | R19: =P19*Q19 -> 23.549071 | S19: 23.54907 | T19: =R19-S19 -> 5.7676433e-07 | U19: Дроссель-клапан: ζ(α) по таблице листа «4 Заслонка» с интерполяцией по ln ζ. Параметр 1 = угол α, °. | V19: Идельчик, 1992 [С][П]
A20: 16 | B20: post2 | C20: tee2 | D20: teeSide | E20: 0.2 | G20: =$G$15 -> 1500.0005 | H20: =$G$21 -> 2999.1107 | J20: 0.315 | L20: =J20 -> 0.315 | M20: =H20/3600/(PI()*L20^2/4) -> 10.690032 | N20: =M20*L20/'1 Исходные'!$D$7 -> 223596.29 | P20: =IF((E20/J20)^2<=0.35,1,MAX(0.9*(1-(G20/H20)),0.55))*(1+((G20/H20)*(J20/E20)^2)^2-2*(1-(G20/H20))^2) -> 1.121772 | Q20: ='1 Исходные'!$D$6*M20^2/2 -> 68.566071 | R20: =P20*Q20 -> 76.915496 | S20: 76.915495 | T20: =R20-S20 -> 1.1201418e-06 | U20: Тройник на слияние, боковой вход. r = Q_б/Q_с. ζ = A·[1 + (r·F_с/F_б)² − 2(1 − r)²], к скорости в общем канале d_с (параметр 1). A: F_б/F_с ≤ 0,35 → 1; иначе max(0,9(1 − r); 0,55). Может быть < 0 (эжекция) — это физика. | V20: Идельчик, 1992, разд. 7, диагр. 7-1 [С][П: сверить таблицу A]
A21: 17 | B21: c2 | C21: c2 | D21: duct | E21: 0.315 | F21: 5 | G21: =$G$12+$G$15 -> 2999.1107 | L21: =E21 -> 0.315 | M21: =G21/3600/(PI()*L21^2/4) -> 10.690032 | N21: =M21*L21/'1 Исходные'!$D$7 -> 223596.29 | O21: =IF(N21<=2000,64/N21,IF(N21>=4000,0.11*('1 Исходные'!$D$10/E21+68/N21)^0.25,(1-(N21-2000)/2000)*64/2000+(N21-2000)/2000*0.11*('1 Исходные'!$D$10/E21+68/4000)^0.25)) -> 0.017368684 | P21: =O21*F21/E21 -> 0.2756934 | Q21: ='1 Исходные'!$D$6*M21^2/2 -> 68.566071 | R21: =P21*Q21 -> 18.903213 | S21: 18.903213 | T21: =R21-S21 -> 1.871213e-07 | U21: Трение по длине: ζ = λ·l/d. λ: Re ≤ 2000 — 64/Re; Re ≥ 4000 — Альтшуль 0,11(kэ/d + 68/Re)^0,25; между — линейно (чтобы λ была непрерывной). | V21: Дарси–Вейсбах; Альтшуль А.Д., 1982 [С]
A22: 18 | B22: c2 | C22: trans_c2 | D22: diffuser | E22: 0.315 | G22: =$G$21 -> 2999.1107 | J22: 0.4 | K22: 15 | L22: =E22 -> 0.315 | M22: =G22/3600/(PI()*L22^2/4) -> 10.690032 | N22: =M22*L22/'1 Исходные'!$D$7 -> 223596.29 | P22: =IF(K22>40,(1-(E22/J22)^2)^2,MIN((1-(E22/J22)^2)^2,3.2*TAN(RADIANS(K22/2))^1.25*(1-(E22/J22)^2)^2)) -> 0.036613928 | Q22: ='1 Исходные'!$D$6*M22^2/2 -> 68.566071 | R22: =P22*Q22 -> 2.5104732 | S22: 2.510473 | T22: =R22-S22 -> 2.0119811e-07 | U22: Переход на больший диаметр (диффузор). n = (1 − F₁/F₂)² — внезапное расширение (Борда–Карно); при угле α ≤ 40°: ζ = 3,2·tg(α/2)^1,25·n, но не больше n. К скорости в узком сечении d₁. Параметр 1 = d₂, м; параметр 2 = α, °. | V22: Идельчик, 1992, разд. 5 [С][П]
A23: 19 | B23: c2 | C23: teeP3 | D23: teeStraight | E23: 0.4 | G23: =$G$21 -> 2999.1107 | H23: =G23+I23 -> 4499.1097 | I23: =$G$24 -> 1499.999 | L23: =E23 -> 0.4 | M23: =H23/3600/(PI()*L23^2/4) -> 9.9452159 | N23: =M23*L23/'1 Исходные'!$D$7 -> 264149.16 | P23: =1.55*(I23/H23)-(I23/H23)^2 -> 0.40561362 | Q23: ='1 Исходные'!$D$6*M23^2/2 -> 59.344392 | R23: =P23*Q23 -> 24.070894 | S23: 24.070893 | T23: =R23-S23 -> 7.650444e-07 | U23: Тройник на слияние, проход. r = Q_б/Q_с (Q_б — боковой поток, колонка I). ζ = 1,55·r − r², к скорости в общем канале (d = d_с). | V23: Идельчик, 1992, разд. 7, диагр. 7-1 [С][П]
A24: 20 | B24: post3 | C24: hood3 | D24: local | E24: 0.2 | G24: 1499.999 | J24: 0.2 | L24: =E24 -> 0.2 | M24: =G24/3600/(PI()*L24^2/4) -> 13.262903 | N24: =M24*L24/'1 Исходные'!$D$7 -> 176134.17 | P24: =J24 -> 0.2 | Q24: ='1 Исходные'!$D$6*M24^2/2 -> 105.54276 | R24: =P24*Q24 -> 21.108552 | S24: 21.108551 | T24: =R24-S24 -> 7.8072319e-07 | U24: Вход через конический зонт (коллектор): ζ = 0,2 (параметр 1). Без зонта (острая кромка) было бы 0,5. | V24: Идельчик, 1992, разд. 3 [С][П: по диаграмме]
A25: 21 | B25: post3 | C25: branch3 | D25: duct | E25: 0.2 | F25: 6 | G25: =$G$24 -> 1499.999 | L25: =E25 -> 0.2 | M25: =G25/3600/(PI()*L25^2/4) -> 13.262903 | N25: =M25*L25/'1 Исходные'!$D$7 -> 176134.17 | O25: =IF(N25<=2000,64/N25,IF(N25>=4000,0.11*('1 Исходные'!$D$10/E25+68/N25)^0.25,(1-(N25-2000)/2000)*64/2000+(N25-2000)/2000*0.11*('1 Исходные'!$D$10/E25+68/4000)^0.25)) -> 0.018978401 | P25: =O25*F25/E25 -> 0.56935202 | Q25: ='1 Исходные'!$D$6*M25^2/2 -> 105.54276 | R25: =P25*Q25 -> 60.090983 | S25: 60.090981 | T25: =R25-S25 -> 1.8616417e-06 | U25: Трение по длине: ζ = λ·l/d. λ: Re ≤ 2000 — 64/Re; Re ≥ 4000 — Альтшуль 0,11(kэ/d + 68/Re)^0,25; между — линейно (чтобы λ была непрерывной). | V25: Дарси–Вейсбах; Альтшуль А.Д., 1982 [С]
A26: 22 | B26: post3 | C26: bend90_3 | D26: local | E26: 0.2 | G26: =$G$24 -> 1499.999 | J26: 90 | K26: 1.5 | L26: =E26 -> 0.2 | M26: =G26/3600/(PI()*L26^2/4) -> 13.262903 | N26: =M26*L26/'1 Исходные'!$D$7 -> 176134.17 | P26: =(0.0000001634831*J26^3-0.000081581126*J26^2+0.01714184*J26)*IF(K26<1,0.21/K26^2.5,0.21/K26^0.5) -> 0.17165935 | Q26: ='1 Исходные'!$D$6*M26^2/2 -> 105.54276 | R26: =P26*Q26 -> 18.117401 | S26: 18.117401 | T26: =R26-S26 -> 3.8319777e-07 | U26: отвод 90°, R/D = 1,5. ζ = A₁·B₁; A₁ = 1,634831·10⁻⁷δ³ − 8,1581126·10⁻⁵δ² + 1,714184·10⁻²δ (A₁(90°) = 1,00); B₁ = 0,21/(R/D)^2,5 при R/D < 1, 0,21/(R/D)^0,5 при R/D ≥ 1. Параметр 1 = δ, °; параметр 2 = R/D. | V26: Идельчик И.Е., 1992, разд. 6, диагр. 6-1 [С][П]
A27: 23 | B27: post3 | C27: bend45_3 | D27: local | E27: 0.2 | G27: =$G$24 -> 1499.999 | J27: 45 | K27: 1.5 | L27: =E27 -> 0.2 | M27: =G27/3600/(PI()*L27^2/4) -> 13.262903 | N27: =M27*L27/'1 Исходные'!$D$7 -> 176134.17 | P27: =(0.0000001634831*J27^3-0.000081581126*J27^2+0.01714184*J27)*IF(K27<1,0.21/K27^2.5,0.21/K27^0.5) -> 0.10649276 | Q27: ='1 Исходные'!$D$6*M27^2/2 -> 105.54276 | R27: =P27*Q27 -> 11.23954 | S27: 11.23954 | T27: =R27-S27 -> 2.0989719e-07 | U27: отвод 45°, R/D = 1,5. ζ = A₁·B₁; A₁ = 1,634831·10⁻⁷δ³ − 8,1581126·10⁻⁵δ² + 1,714184·10⁻²δ (A₁(90°) = 1,00); B₁ = 0,21/(R/D)^2,5 при R/D < 1, 0,21/(R/D)^0,5 при R/D ≥ 1. Параметр 1 = δ, °; параметр 2 = R/D. | V27: Идельчик И.Е., 1992, разд. 6, диагр. 6-1 [С][П]
A28: 24 | B28: post3 | C28: damper3 | D28: damper | E28: 0.2 | G28: =$G$24 -> 1499.999 | J28: 6.865851 | L28: =E28 -> 0.2 | M28: =G28/3600/(PI()*L28^2/4) -> 13.262903 | N28: =M28*L28/'1 Исходные'!$D$7 -> 176134.17 | P28: =IF(J28>=90,10000,EXP(LN(INDEX('4 Заслонка'!$B$5:$B$20,MATCH(J28,'4 Заслонка'!$A$5:$A$20,1)))+(J28-INDEX('4 Заслонка'!$A$5:$A$20,MATCH(J28,'4 Заслонка'!$A$5:$A$20,1)))/(INDEX('4 Заслонка'!$A$5:$A$20,MATCH(J28,'4 Заслонка'!$A$5:$A$20,1)+1)-INDEX('4 Заслонка'!$A$5:$A$20,MATCH(J28,'4 Заслонка'!$A$5:$A$20,1)))*(LN(INDEX('4 Заслонка'!$B$5:$B$20,MATCH(J28,'4 Заслонка'!$A$5:$A$20,1)+1))-LN(INDEX('4 Заслонка'!$B$5:$B$20,MATCH(J28,'4 Заслонка'!$A$5:$A$20,1)))))) -> 0.32027191 | Q28: ='1 Исходные'!$D$6*M28^2/2 -> 105.54276 | R28: =P28*Q28 -> 33.802381 | S28: 33.802381 | T28: =R28-S28 -> -1.9386253e-07 | U28: Дроссель-клапан: ζ(α) по таблице листа «4 Заслонка» с интерполяцией по ln ζ. Параметр 1 = угол α, °. | V28: Идельчик, 1992 [С][П]
A29: 25 | B29: post3 | C29: tee3 | D29: teeSide | E29: 0.2 | G29: =$G$24 -> 1499.999 | H29: =$G$30 -> 4499.1097 | J29: 0.4 | L29: =J29 -> 0.4 | M29: =H29/3600/(PI()*L29^2/4) -> 9.9452159 | N29: =M29*L29/'1 Исходные'!$D$7 -> 264149.16 | P29: =IF((E29/J29)^2<=0.35,1,MAX(0.9*(1-(G29/H29)),0.55))*(1+((G29/H29)*(J29/E29)^2)^2-2*(1-(G29/H29))^2) -> 1.8897655 | Q29: ='1 Исходные'!$D$6*M29^2/2 -> 59.344392 | R29: =P29*Q29 -> 112.14698 | S29: 112.14698 | T29: =R29-S29 -> 3.0396241e-06 | U29: Тройник на слияние, боковой вход. r = Q_б/Q_с. ζ = A·[1 + (r·F_с/F_б)² − 2(1 − r)²], к скорости в общем канале d_с (параметр 1). A: F_б/F_с ≤ 0,35 → 1; иначе max(0,9(1 − r); 0,55). Может быть < 0 (эжекция) — это физика. | V29: Идельчик, 1992, разд. 7, диагр. 7-1 [С][П: сверить таблицу A]
A30: 26 | B30: c3 | C30: c3 | D30: duct | E30: 0.4 | F30: 10 | G30: =$G$21+$G$24 -> 4499.1097 | L30: =E30 -> 0.4 | M30: =G30/3600/(PI()*L30^2/4) -> 9.9452159 | N30: =M30*L30/'1 Исходные'!$D$7 -> 264149.16 | O30: =IF(N30<=2000,64/N30,IF(N30>=4000,0.11*('1 Исходные'!$D$10/E30+68/N30)^0.25,(1-(N30-2000)/2000)*64/2000+(N30-2000)/2000*0.11*('1 Исходные'!$D$10/E30+68/4000)^0.25)) -> 0.016509609 | P30: =O30*F30/E30 -> 0.41274022 | Q30: ='1 Исходные'!$D$6*M30^2/2 -> 59.344392 | R30: =P30*Q30 -> 24.493818 | S30: 24.493817 | T30: =R30-S30 -> 6.5651554e-07 | U30: Трение по длине: ζ = λ·l/d. λ: Re ≤ 2000 — 64/Re; Re ≥ 4000 — Альтшуль 0,11(kэ/d + 68/Re)^0,25; между — линейно (чтобы λ была непрерывной). | V30: Дарси–Вейсбах; Альтшуль А.Д., 1982 [С]
A31: 27 | B31: c3 | C31: bend_main | D31: local | E31: 0.4 | G31: =$G$30 -> 4499.1097 | J31: 90 | K31: 1.5 | L31: =E31 -> 0.4 | M31: =G31/3600/(PI()*L31^2/4) -> 9.9452159 | N31: =M31*L31/'1 Исходные'!$D$7 -> 264149.16 | P31: =(0.0000001634831*J31^3-0.000081581126*J31^2+0.01714184*J31)*IF(K31<1,0.21/K31^2.5,0.21/K31^0.5) -> 0.17165935 | Q31: ='1 Исходные'!$D$6*M31^2/2 -> 59.344392 | R31: =P31*Q31 -> 10.18702 | S31: 10.18702 | T31: =R31-S31 -> -2.2097367e-07 | U31: отвод 90° к фильтру. ζ = A₁·B₁; A₁ = 1,634831·10⁻⁷δ³ − 8,1581126·10⁻⁵δ² + 1,714184·10⁻²δ (A₁(90°) = 1,00); B₁ = 0,21/(R/D)^2,5 при R/D < 1, 0,21/(R/D)^0,5 при R/D ≥ 1. Параметр 1 = δ, °; параметр 2 = R/D. | V31: Идельчик И.Е., 1992, разд. 6, диагр. 6-1 [С][П]
A32: 28 | B32: common | C32: filter | D32: filter | G32: =$G$30 -> 4499.1097 | J32: 400 | K32: 4500 | R32: =J32*(G32/K32) -> 399.92086 | S32: 399.92086 | T32: =R32-S32 -> 4.2222222e-06 | U32: Фильтр: Δp = Δp_ном·(Q/Q_ном)^m, m = 1 (закон Дарси для фильтровальной перегородки). Параметр 1 = Δp_ном, Па; параметр 2 = Q_ном, м³/ч. Чистый фильтр (k_загр = 1). | V32: Ужов В.Н., Мягков Б.И., 1970 [С]; Δp_ном — паспорт [Д]
A33: 29 | B33: common | C33: discharge | D33: duct | E33: 0.4 | F33: 5 | G33: =$G$32 -> 4499.1097 | L33: =E33 -> 0.4 | M33: =G33/3600/(PI()*L33^2/4) -> 9.9452159 | N33: =M33*L33/'1 Исходные'!$D$7 -> 264149.16 | O33: =IF(N33<=2000,64/N33,IF(N33>=4000,0.11*('1 Исходные'!$D$10/E33+68/N33)^0.25,(1-(N33-2000)/2000)*64/2000+(N33-2000)/2000*0.11*('1 Исходные'!$D$10/E33+68/4000)^0.25)) -> 0.016509609 | P33: =O33*F33/E33 -> 0.20637011 | Q33: ='1 Исходные'!$D$6*M33^2/2 -> 59.344392 | R33: =P33*Q33 -> 12.246909 | S33: 12.246909 | T33: =R33-S33 -> -1.7174223e-07 | U33: Трение по длине: ζ = λ·l/d. λ: Re ≤ 2000 — 64/Re; Re ≥ 4000 — Альтшуль 0,11(kэ/d + 68/Re)^0,25; между — линейно (чтобы λ была непрерывной). | V33: Дарси–Вейсбах; Альтшуль А.Д., 1982 [С]
A34: 30 | B34: common | C34: bend_out | D34: local | E34: 0.4 | G34: =$G$32 -> 4499.1097 | J34: 90 | K34: 1.5 | L34: =E34 -> 0.4 | M34: =G34/3600/(PI()*L34^2/4) -> 9.9452159 | N34: =M34*L34/'1 Исходные'!$D$7 -> 264149.16 | P34: =(0.0000001634831*J34^3-0.000081581126*J34^2+0.01714184*J34)*IF(K34<1,0.21/K34^2.5,0.21/K34^0.5) -> 0.17165935 | Q34: ='1 Исходные'!$D$6*M34^2/2 -> 59.344392 | R34: =P34*Q34 -> 10.18702 | S34: 10.18702 | T34: =R34-S34 -> -2.2097367e-07 | U34: отвод 90° на выбросе. ζ = A₁·B₁; A₁ = 1,634831·10⁻⁷δ³ − 8,1581126·10⁻⁵δ² + 1,714184·10⁻²δ (A₁(90°) = 1,00); B₁ = 0,21/(R/D)^2,5 при R/D < 1, 0,21/(R/D)^0,5 при R/D ≥ 1. Параметр 1 = δ, °; параметр 2 = R/D. | V34: Идельчик И.Е., 1992, разд. 6, диагр. 6-1 [С][П]
A35: 31 | B35: common | C35: exit | D35: local | E35: 0.4 | G35: =$G$32 -> 4499.1097 | J35: 1 | L35: =E35 -> 0.4 | M35: =G35/3600/(PI()*L35^2/4) -> 9.9452159 | N35: =M35*L35/'1 Исходные'!$D$7 -> 264149.16 | P35: =J35 -> 1 | Q35: ='1 Исходные'!$D$6*M35^2/2 -> 59.344392 | R35: =P35*Q35 -> 59.344392 | S35: 59.344391 | T35: =R35-S35 -> 1.1533505e-06 | U35: Выход в атмосферу: теряется вся скорость, ζ = 1 (параметр 1). | V35: Идельчик, 1992 [С]
B37: Суммы потерь по участкам и путям
B38: Участок / путь | R38: Σ Δp, Па (Excel) | S38: Σ Δp, Па (ядро) | T38: Разница | U38: Пояснение
B39: post1 | R39: =SUMIF($B$5:$B$35,B39,$R$5:$R$35) -> 157.14283 | S39: =SUMIF($B$5:$B$35,B39,$S$5:$S$35) -> 157.14283 | T39: =R39-S39 -> 2.7066646e-06
B40: c1 | R40: =SUMIF($B$5:$B$35,B40,$R$5:$R$35) -> 53.878423 | S40: =SUMIF($B$5:$B$35,B40,$S$5:$S$35) -> 53.878423 | T40: =R40-S40 -> -8.8808982e-08
B41: post2 | R41: =SUMIF($B$5:$B$35,B41,$R$5:$R$35) -> 211.02126 | S41: =SUMIF($B$5:$B$35,B41,$S$5:$S$35) -> 211.02125 | T41: =R41-S41 -> 3.500003e-06
B42: c2 | R42: =SUMIF($B$5:$B$35,B42,$R$5:$R$35) -> 45.48458 | S42: =SUMIF($B$5:$B$35,B42,$S$5:$S$35) -> 45.484579 | T42: =R42-S42 -> 1.1533638e-06
...

Sheet 6 Вентилятор
A1: Вентилятор: давление, мощность, КПД привода
A2: Давление вентилятора при частоте n — по каталожной характеристике (при n₀) и законам подобия: Q ~ n, p ~ n². Мощность на валу N = Q·p/η. Электрическая мощность — с учётом КПД двигателя и частотника.
A4: № | B4: Величина | C4: Обозн. | D4: Значение | E4: Ед. | F4: Формула (как в книге) | G4: Простыми словами — что это и зачем | H4: Источник / статус
A5: Характеристика вентилятора при n₀ (демо [Д] — заменить каталогом)
B6: Q₀, м³/ч | C6: p₀, Па
B7: 0 | C7: 1400
B8: 2000 | C8: 1300
B9: 4000 | C9: 1050
B10: 5000 | C10: 850
B11: 6000 | C11: 550
B12: 7000 | C12: 150
A14: 1 | B14: Частота каталожной характеристики | C14: n₀ | D14: 1500 | E14: об/мин | H14: каталог [Д]
A15: 2 | B15: Частота после пусконаладки | C15: n | D15: 1400.6836 | E15: об/мин | G15: Минимальная частота, при которой все посты получают 1500 м³/ч (подобрано ядром, balance.ts). | H15: ядро
A16: 3 | B16: Общий расход | C16: Q | D16: ='5 Потери'!$G$32 -> 4499.1097 | E16: м³/ч | F16: Q = ΣQ_пост | H16: лист 5
A17: 4 | B17: Отношение частот | C17: k | D17: ='6 Вентилятор'!$D$15/'6 Вентилятор'!$D$14 -> 0.93378906 | E17: — | F17: k = n/n₀
A18: 5 | B18: Расход, приведённый к n₀ | C18: Q₀ | D18: ='6 Вентилятор'!$D$16/'6 Вентилятор'!$D$17 -> 4818.1221 | E18: м³/ч | F18: Q₀ = Q/k | G18: По закону подобия расход пропорционален частоте. | H18: ГОСТ 10921-2017, разд. 14 [Н]
A19: 6 | B19: Давление по характеристике при n₀ | C19: p₀ | D19: =INDEX('6 Вентилятор'!$C$7:$C$12,MATCH('6 Вентилятор'!$D$18,'6 Вентилятор'!$B$7:$B$12,1))+('6 Вентилятор'!$D$18-INDEX('6 Вентилятор'!$B$7:$B$12,MATCH('6 Вентилятор'!$D$18,'6 Вентилятор'!$B$7:$B$12,1)))*(INDEX('6 Вентилятор'!$C$7:$C$12,MATCH('6 Вентилятор'!$D$18,'6 Вентилятор'!$B$7:$B$12,1)+1)-INDEX('6 Вентилятор'!$C$7:$C$12,MATCH('6 Вентилятор'!$D$18,'6 Вентилятор'!$B$7:$B$12,1)))/(INDEX('6 Вентилятор'!$B$7:$B$12,MATCH('6 Вентилятор'!$D$18,'6 Вентилятор'!$B$7:$B$12,1)+1)-INDEX('6 Вентилятор'!$B$7:$B$12,MATCH('6 Вентилятор'!$D$18,'6 Вентилятор'!$B$7:$B$12,1))) -> 886.37558 | E19: Па | F19: линейная интерполяция по таблице
A20: 7 | B20: Давление вентилятора при n | C20: p | D20: ='6 Вентилятор'!$D$19*'6 Вентилятор'!$D$17^2 -> 772.88584 | E20: Па | F20: p = p₀·k² | G20: Давление пропорционально квадрату частоты. | H20: ГОСТ 10921-2017, разд. 14 [Н]
A21: Проверка баланса: давление вентилятора = потери по пути каждого поста
A22: 8 | B22: Путь поста 1 − давление вентилятора | D22: ='5 Потери'!$R$47-'6 Вентилятор'!$D$20 -> 1.8030719e-05 | E22: Па | F22: Σ Δp − p | G22: Должно быть ≈ 0 (± 0,01 Па): расходы — действительно решение сети. | H22: закон сохранения энергии
A23: 9 | B23: Путь поста 2 − давление вентилятора | D23: ='5 Потери'!$R$48-'6 Вентилятор'!$D$20 -> 1.8912867e-05 | E23: Па
A24: 10 | B24: Путь поста 3 − давление вентилятора | D24: ='5 Потери'!$R$49-'6 Вентилятор'!$D$20 -> 2.1340721e-05 | E24: Па
A25: Мощность
A26: 11 | B26: КПД вентилятора | C26: η_в | D26: 0.65 | E26: — | G26: Принят постоянным [Д] — уточнить по каталогу. | H26: [Д]
A27: 12 | B27: Мощность на валу | C27: N | D27: ='6 Вентилятор'!$D$16/3600*'6 Вентилятор'!$D$20/'6 Вентилятор'!$D$26 -> 1486.0249 | E27: Вт | F27: N = Q·p/η_в | H27: Калинушкин М.П., 1979 [С]
A28: 13 | B28: Номинальная мощность двигателя | C28: P_н | D28: 2200 | E28: Вт | H28: демо [Д]
A29: 14 | B29: Номинальный КПД двигателя (IE3, 4 полюса, 2,2 кВт) | C29: η_н | D29: 0.867 | E29: — | H29: ГОСТ IEC 60034-30-1-2016, табл. 1 [Н]
A30: 15 | B30: Загрузка двигателя | C30: β | D30: ='6 Вентилятор'!$D$27/'6 Вентилятор'!$D$28 -> 0.67546585 | E30: — | F30: β = N/P_н
A31: 16 | B31: Отношение постоянных потерь к переменным | C31: k_п | D31: 0.5 | E31: — | G31: Постоянные потери (сталь, трение) не зависят от нагрузки, переменные (медь) ~ β². | H31: Копылов И.П. Электрические машины [С][П]
A32: 17 | B32: КПД двигателя при загрузке β | C32: η_дв | D32: ='6 Вентилятор'!$D$30/('6 Вентилятор'!$D$30+(1/'6 Вентилятор'!$D$29-1)*('6 Вентилятор'!$D$31+'6 Вентилятор'!$D$30^2)/(1+'6 Вентилятор'!$D$31)) -> 0.87352962 | E32: — | F32: η = β/(β + ΣP(β)), ΣP = ΣP_н·(k + β²)/(1 + k) | G32: При недогрузке КПД двигателя падает. | H32: Копылов [С]
A33: 18 | B33: КПД частотника при загрузке β | C33: η_ПЧ | D33: =IF('6 Вентилятор'!$D$30<=0.016,0.35,IF('6 Вентилятор'!$D$30>=1,0.95,INDEX('6 Вентилятор'!$C$36:$I$36,MATCH('6 Вентилятор'!$D$30,'6 Вентилятор'!$C$35:$I$35,1))+('6 Вентилятор'!$D$30-INDEX('6 Вентилятор'!$C$35:$I$35,MATCH('6 Вентилятор'!$D$30,'6 Вентилятор'!$C$35:$I$35,1)))*(INDEX('6 Вентилятор'!$C$36:$I$36,MATCH('6 Вентилятор'!$D$30,'6 Вентилятор'!$C$35:$I$35,1)+1)-INDEX('6 Вентилятор'!$C$36:$I$36,MATCH('6 Вентилятор'!$D$30,'6 Вентилятор'!$C$35:$I$35,1)))/(INDEX('6 Вентилятор'!$C$35:$I$35,MATCH('6 Вентилятор'!$D$30,'6 Вентилятор'!$C$35:$I$35,1)+1)-INDEX('6 Вентилятор'!$C$35:$I$35,MATCH('6 Вентилятор'!$D$30,'6 Вентилятор'!$C$35:$I$35,1))))) -> 0.93403727 | E33: — | F33: интерполяция таблицы | G33: Российского числового норматива нет (метод — ГОСТ IEC 61800-9-2-2021); до паспорта ПЧ — типовые значения US DOE (зарубежный справочный). | H33: [Д]
B35: Таблица КПД ПЧ: β → | C35: 0.016 | D35: 0.125 | E35: 0.25 | F35: 0.42 | G35: 0.5 | H35: 0.75 | I35: 1
C36: 0.35 | D36: 0.8 | E36: 0.88 | F36: 0.91 | G36: 0.92 | H36: 0.94 | I36: 0.95
A38: 19 | B38: Электрическая мощность из сети | C38: P_эл | D38: ='6 Вентилятор'!$D$27/('6 Вентилятор'!$D$32*'6 Вентилятор'!$D$33) -> 1821.3115 | E38: Вт | F38: P_эл = N/(η_дв·η_ПЧ) | G38: Это то, что покажет счётчик.

Sheet 7 Тепло
A1: Тепло на нагрев приточного воздуха
A2: Весь воздух, удалённый из цеха (местные отсосы + общеобменная), замещается наружным, который надо нагреть до t_в. Q = ρ·c·L·(t_в − t_н).
A4: № | B4: Величина | C4: Обозн. | D4: Значение | E4: Ед. | F4: Формула (как в книге) | G4: Простыми словами — что это и зачем | H4: Источник / статус
A5: 1 | B5: Разность температур | C5: Δt | D5: ='1 Исходные'!$D$31-'1 Исходные'!$D$32 -> 19.7 | E5: °C | F5: Δt = t_в − t_оп | H5: СанПиН, СП 131.13330.2025
A6: Без регулирования: всё работает всю смену на расчётном расходе
A7: 2 | B7: Весь удаляемый воздух | C7: L | D7: ='3 СП 60'!$D$6+'3 СП 60'!$D$11 -> 12601.449 | E7: м³/ч | F7: L = L_wz + L_оо | G7: Равно L по СП 60 (лист 3). | H7: лист 3
A8: 3 | B8: Тепловая мощность | C8: Φ | D8: ='1 Исходные'!$D$6*'1 Исходные'!$D$8*'7 Тепло'!$D$7/3600*'7 Тепло'!$D$5 -> 83.16326 | E8: кВт | F8: Φ = ρ·c·L·Δt/3600 | G8: Сколько киловатт тепла идёт на подогрев притока. | H8: Богословский В.Н. и др. Отопление и вентиляция, 1976 [С]
A9: 4 | B9: Тепло за смену | C9: Q_см | D9: ='7 Тепло'!$D$8*'1 Исходные'!$D$34 -> 665.30608 | E9: кВт·ч | F9: Q = Φ·t_см | G9: Сверка с ядром: режим «без регулирования» лист 9.
A10: 5 | B10: Тепло за отопительный период (1 смена/сут) | C10: Q_оп | D10: ='7 Тепло'!$D$9*'1 Исходные'!$D$33/1000 -> 134.39183 | E10: МВт·ч | F10: Q_см·z_оп
A11: 6 | B11: То же в гигакалориях | D11: ='7 Тепло'!$D$10/1.163 -> 115.55617 | E11: Гкал | F11: 1 Гкал = 1,163 МВт·ч | G11: В Гкал выставляют счёт за тепло.
A12: Сколько стоил бы «двойной учёт» воздуха отсосов (ошибка до 11.10.2026)
A13: 7 | B13: Лишнее тепло за смену | C13: ΔQ | D13: ='1 Исходные'!$D$6*'1 Исходные'!$D$8*'3 СП 60'!$D$15/3600*'7 Тепло'!$D$5*'1 Исходные'!$D$34 -> 237.582 | E13: кВт·ч | G13: Столько тепла «лишнего» закладывал старый расчёт.

Sheet 8 Сверка
A1: Сверка: Excel против расчётного ядра
A2: Ядро — программа vent-sim (TypeScript); значения выгружены export_engine.ts в engine.json. Зелёный — расхождение < 0,1 %.
A4: Величина | B4: Excel | C4: Ядро | D4: Относит. разница | E4: Итог
A5: Коэффициент расплавления α_р, г/(А·ч), 225 А | B5: ='2 Выделения'!$D$6 -> 9.7765625 | C5: 9.7765625 | D5: =ABS(B5-C5)/ABS(C5) -> 0 | E5: =IF(D5<0.001,"ОК","ПРОВЕРИТЬ") -> ОК
A6: Расход проволоки B, кг/ч, 225 А | B6: ='2 Выделения'!$D$7 -> 2.1997266 | C6: 2.1997266 | D6: =ABS(B6-C6)/ABS(C6) -> 0 | E6: =IF(D6<0.001,"ОК","ПРОВЕРИТЬ") -> ОК
A7: Весь воздухообмен L по СП 60, м³/ч (3 поста, 225 А) | B7: ='3 СП 60'!$D$10 -> 12601.449 | C7: 12601.449 | D7: =ABS(B7-C7)/ABS(C7) -> 0 | E7: =IF(D7<0.001,"ОК","ПРОВЕРИТЬ") -> ОК
A8: Общеобменная L_оо = L − L_wz, м³/ч | B8: ='3 СП 60'!$D$11 -> 8101.4486 | C8: 8101.4486 | D8: =ABS(B8-C8)/ABS(C8) -> 0 | E8: =IF(D8<0.001,"ОК","ПРОВЕРИТЬ") -> ОК
A9: Расход вентилятора, м³/ч | B9: ='6 Вентилятор'!$D$16 -> 4499.1097 | C9: 4499.1097 | D9: =ABS(B9-C9)/ABS(C9) -> 1.0037788e-08 | E9: =IF(D9<0.001,"ОК","ПРОВЕРИТЬ") -> ОК
A10: Давление вентилятора, Па | B10: ='6 Вентилятор'!$D$20 -> 772.88584 | C10: 772.88585 | D10: =ABS(B10-C10)/ABS(C10) -> 1.0361586e-08 | E10: =IF(D10<0.001,"ОК","ПРОВЕРИТЬ") -> ОК
A11: Мощность на валу, Вт | B11: ='6 Вентилятор'!$D$27 -> 1486.0249 | C11: 1486.0249 | D11: =ABS(B11-C11)/ABS(C11) -> 3.2379872e-10 | E11: =IF(D11<0.001,"ОК","ПРОВЕРИТЬ") -> ОК
A12: КПД двигателя при загрузке | B12: ='6 Вентилятор'!$D$32 -> 0.87352962 | C12: 0.87352962 | D12: =ABS(B12-C12)/ABS(C12) -> 1.8735252e-12 | E12: =IF(D12<0.001,"ОК","ПРОВЕРИТЬ") -> ОК
A13: Электрическая мощность, Вт | B13: ='6 Вентилятор'!$D$38 -> 1821.3115 | C13: 1821.3115 | D13: =ABS(B13-C13)/ABS(C13) -> 3.0319244e-10 | E13: =IF(D13<0.001,"ОК","ПРОВЕРИТЬ") -> ОК
A14: Тепло за смену без регулирования, кВт·ч | B14: ='7 Тепло'!$D$9 -> 665.30608 | C14: 665 | D14: =ABS(B14-C14)/ABS(C14) -> 0.00046027504 | E14: =IF(D14<0.001,"ОК","ПРОВЕРИТЬ") -> ОК
A15: Тепло за смену в ядре — результат динамического расчёта (интеграл за 8 ч), округлён до 1 кВт·ч, поэтому разница до 0,1 %.
A16: Наибольшее расхождение потерь по элементу, Па | B16: ='5 Потери'!$R$51 -> 4.2222222e-06 | C16: допуск 0.001 | E16: =IF(ABS(B16)<=0.001,"ОК","ПРОВЕРИТЬ") -> ОК
A17: Баланс: путь поста 1 − давление вентилятора, Па | B17: ='6 Вентилятор'!$D$22 -> 1.8030719e-05 | C17: допуск 0.01 | E17: =IF(ABS(B17)<=0.01,"ОК","ПРОВЕРИТЬ") -> ОК
A18: Баланс: путь поста 2 − давление вентилятора, Па | B18: ='6 Вентилятор'!$D$23 -> 1.8912867e-05 | C18: допуск 0.01 | E18: =IF(ABS(B18)<=0.01,"ОК","ПРОВЕРИТЬ") -> ОК
A19: Баланс: путь поста 3 − давление вентилятора, Па | B19: ='6 Вентилятор'!$D$24 -> 2.1340721e-05 | C19: допуск 0.01 | E19: =IF(ABS(B19)<=0.01,"ОК","ПРОВЕРИТЬ") -> ОК
A20: Проверка выделений: Σ компонентов − аэрозоль, г/кг | B20: ='2 Выделения'!$D$13 -> 0 | C20: допуск 1e-09 | E20: =IF(ABS(B20)<=0.000000001,"ОК","ПРОВЕРИТЬ") -> ОК
A21: Концентрация Mn при L по СП 60 минус ПДК, мг/м³ | B21: ='3 СП 60'!$D$13-'1 Исходные'!$D$25 -> 0 | C21: допуск 1e-09 | E21: =IF(ABS(B21)<=0.000000001,"ОК","ПРОВЕРИТЬ") -> ОК

Sheet 9 Результаты смены
A1: Итоги динамического расчёта смены 8 ч (ядро, шаг 1 с) — версия 1.6 от 11.10.2026
A2: Эти числа получены программой: расписание сварки, регуляторы, приводы заслонок с ограниченной скоростью, частотник, решение сети на каждом шаге, нестационарная концентрация в цехе. В Excel повторить нельзя; проверяемые части (выделения, СП 60, потери, вентилятор, тепло) — на листах 2–7.
A4: А. 3 поста MAG 225 А, общеобменная постоянная 8 101 м³/ч (по СП 60)
A5: Режим местной вытяжки | B5: Вент. МВВ, кВт·ч | C5: Тепло, кВт·ч | D5: Ср. расход МВВ, м³/ч | E5: Расход < 95 % | F5: > 110 % | G5: Mn ср., мг/м³ | H5: Mn макс., мг/м³
A6: Без регулирования | B6: 14.57 | C6: 665 | D6: 4497 | E6: 0 % | F6: 0 % | G6: 0.064 | H6: 0.088
A7: «Открыто/закрыто» + ПЧ (пром. стандарт) | B7: 5.25 | C7: 527 | D7: 1887 | E7: 6,0 % | F7: 39,1 % | G7: 0.085 | H7: 0.111
A8: Предлагаемая (ПИ по ln ζ + сброс давления) | B8: 4.92 | C8: 519 | D8: 1727 | E8: 5,9 % | F8: 3,0 % | G8: 0.087 | H8: 0.115
A9: Предлагаемая + ОВ по числу постов | B9: 4.92 | C9: 398 | D9: 1727 | E9: 5,9 % | F9: 3,0 % | G9: 0.107 | H9: 0.143
A11: Б. 3 поста, ток меняется 175/225/270 А; режимы общеобменной (местная — предлагаемая)
A12: Режим ОВ | B12: Ср. ОВ, м³/ч | C12: Тепло, кВт·ч | D12: Эл. МВВ+ОВ, кВт·ч | E12: Mn ср. | F12: Mn макс. | G12: Время > ПДК
A13: Постоянный (расчётный, 270 А) | B13: 10847 | C13: 660 | D13: 28.74 | E13: 0.069 | F13: 0.096 | G13: 0 %
A14: По числу работающих постов | B14: 5344 | C14: 369 | D14: 9.39 | E14: 0.106 | F14: 0.144 | G14: 0 %
A15: Упреждение по току | B15: 7539 | C15: 485 | D15: 6.12 | E15: 0.086 | F15: 0.112 | G15: 0 %
A16: Упреждение по току + датчик (цель 0,5 ПДК) | B16: 6920 | C16: 453 | D16: 6.56 | E16: 0.089 | F16: 0.115 | G16: 0 %
A17: То же, цель 0,7 ПДК | B17: 4190 | C17: 308 | D17: 6 | E17: 0.115 | F17: 0.154 | G17: 0 %
A18: Ошибка модели: реальный захват 70 % вместо 80 % — постоянный | B18: 10847 | C18: 660 | D18: 28.74 | E18: 0.098 | F18: 0.137 | G18: 0 %
A19: Ошибка модели — упреждение без датчика | B19: 7539 | C19: 485 | D19: 6.12 | E19: 0.122 | F19: 0.159 | G19: 0 %
A20: Ошибка модели — упреждение + датчик (сам добавил воздух) | B20: 11047 | C20: 670 | D20: 12.05 | E20: 0.092 | F20: 0.123 | G20: 0 %
A22: В. Цех из 4 видов сварки (CO₂ 225 А · УОНИ-13/45 · ФЦ-12 · контактная); местные отсосы 5 500 м³/ч, ОВ по СП 60 — 1 022 м³/ч
A23: МВВ / ОВ | B23: Вент. МВВ, кВт·ч | C23: Тепло, кВт·ч | D23: Ср. ОВ, м³/ч | E23: max Σ C/ПДК
A24: Без регулирования / пост. | B24: 20.11 | C24: 344 | D24: 1022 | E24: 0.382
A25: «Открыто/закрыто» + ПЧ / пост. | B25: 7.59 | C25: 181 | D25: 1022 | E25: 0.646
A26: Предлагаемая / пост. | B26: 6.45 | C26: 166 | D26: 1022 | E26: 0.709
A27: Предлагаемая / по числу постов | B27: 6.45 | C27: 139 | D27: 517 | E27: 0.779
A28: Предлагаемая / по выделениям + датчики, цель 0,5 | B28: 6.45 | C28: 274 | D28: 3082 | E28: 0.491
A29: то же, цель 0,8 (та же безопасность, что у пост.) | B29: 6.45 | C29: 155 | D29: 811 | E29: 0.718
A30: то же, цель 0,9 | B30: 6.45 | C30: 135 | D30: 446 | E30: 0.775
A32: ВЫВОДЫ (после исправлений 11.10.2026):
A33: 1. Основная экономия электроэнергии — от регулирования местной вытяжки: «открыто/закрыто» + ПЧ даёт −64 % против работы без регулирования; предлагаемая система — ещё −6 % и, главное, точность: перерасход 3 % времени против 39 %.
A34: 2. Общеобменная по потребности — это компромисс «тепло ↔ запас по ПДК». При той же безопасности, что у постоянной (max Σ C/ПДК ≈ 0,71), экономия тепла всего −7 % (166 → 155 кВт·ч, таблица В); при допуске до 0,9 ПДК — до −19 %. Прежние цифры (−37…−56 %) были завышены из-за двойного учёта воздуха отсосов.
A35: 3. Простое регулирование «по числу работающих постов» даёт почти тот же результат, что сложное по выделениям (таблица Б: 369 кВт·ч при Mn макс. 0,144).
A36: 4. Датчик нужен для безопасности, а не для экономии: при ошибке модели (захват 70 % вместо 80 %) система с датчиком сама добавила воздух (Mn макс. 0,123), без датчика — 0,159.
A37: 5. Связь местной и общеобменной: при снижении расходов отсосов уменьшается разбавление воздуха цеха, общеобменная должна это компенсировать — это аргумент за СОГЛАСОВАННОЕ управление (новизна).
A38: 6. Зона дыхания сварщика: при η = 0,8 концентрация у лица в 7 раз выше фона цеха и выше ПДК во всех режимах; ПДК в зоне дыхания обеспечивается только захватом η ≥ 0,93 — определяет конструкция отсоса, а не воздухообмен.
